Workbook

Sheet 工程研发事业部人员名单
A1: 序号 | B1: 姓名 | C1: 胸卡号 | D1: 专业室
A2: =ROW()-1 -> 1 | B2: 毛磊凯 | C2: 51184 | D2: 办公室
A3: =ROW()-1 -> 2 | B3: 刘杰 | C3: 17242 | D3: 办公室
A4: =ROW()-1 -> 3 | B4: 宋凯（总体） | C4: 22260 | D4: 办公室
A5: =ROW()-1 -> 4 | B5: 张继斌 | C5: 17243 | D5: 总体室
A6: =ROW()-1 -> 5 | B6: 赵婷 | C6: 50702 | D6: 总体室
A7: =ROW()-1 -> 6 | B7: 刘聪 | C7: 52018 | D7: 总体室
A8: =ROW()-1 -> 7 | B8: 刘全 | C8: 50874 | D8: 总体室
A9: =ROW()-1 -> 8 | B9: 秦超 | C9: 51591 | D9: 总体室
A10: =ROW()-1 -> 9 | B10: 尤宏良 | C10: 18550 | D10: 总体室
A11: =ROW()-1 -> 10 | B11: 任璐璐 | C11: 50032 | D11: 总体室
A12: =ROW()-1 -> 11 | B12: 赵长辉 | C12: 17725 | D12: 总体室
A13: =ROW()-1 -> 12 | B13: 刘成 | C13: 51860 | D13: 总体室
... A118: =ROW()-1 -> 117 | B118: 林树德 | C118: 51202 | D118: 综合技术室
A119: =ROW()-1 -> 118 | B119: 孙红军 | C119: 02501 | D119: 综合技术室
A120: =ROW()-1 -> 119 | B120: 陈志禹 | C120: 17787 | D120: 综合技术室
A121: =ROW()-1 -> 120 | B121: 王琛 | C121: 22291 | D121: 综合技术室
A122: =ROW()-1 -> 121 | B122: 王勇 | C122: 51226 | D122: 综合技术室
A123: =ROW()-1 -> 122 | B123: 潘英 | C123: 50864 | D123: 综合技术室
A124: =ROW()-1 -> 123 | B124: 杨琼 | C124: 26828 | D124: 综合技术室
A125: =ROW()-1 -> 124 | B125: 宋建毅 | C125: 27100 | D125: 综合技术室
A126: =ROW()-1 -> 125 | B126: 孙盘滔 | C126: 50686 | D126: 综合技术室
A127: =ROW()-1 -> 126 | B127: 吕冬兰 | C127: 51160 | D127: 综合技术室
A128: =ROW()-1 -> 127 | B128: 刘红双 | C128: 51151 | D128: 综合技术室
A129: =ROW()-1 -> 128 | B129: 李其鹏 | C129: 51429 | D129: 综合技术室
A130: =ROW()-1 -> 129 | B130: 王超 | C130: 26621 | D130: 联络工程室
A131: =ROW()-1 -> 130 | B131: 崔明慧 | C131: 14901 | D131: 联络工程室
... A165: =ROW()-1 -> 164 | B165: 王瑞龙 | C165: 26654 | D165: 联络工程室

Sheet 项目简称
A1: CR929设计（2022年上飞院）
A2: CR929设计（2022年复材中心）
A3: C919设计（2020年上飞院）
A4: C919设计（2021年上飞院）
A5: C919设计（2022年上飞院）
A6: C919设计（2020年复材中心）
A7: CR929设计（2021年上飞院）
A8: CR929设计（2021年复材中心）
A9: ARJ21基本型设计（2020年上飞院）
A10: ARJ21货运型设计（2021年上飞院）
A11: ARJ上飞装备
A12: 1号设计（2022年KTB）
... A23: 临时工程支持

Sheet X月项目工时
A1: 序号 | B1: 姓名 | C1: 胸卡号 | D1: 专业室 | E1: 项目简称 | F1: 个人原始项目工时之和/h | G1: 第一年跨专业原始项目工时/h | H1: 第二年跨专业原始项目工时/h | I1: 沈阳工时/h | J1: 市外出差工时/h | K1: 专业 | L1: 工作包 | M1: 主要工作任务 （请简要说明每项设计任务、工时及所属任务通知单编号） 例：序号.工作包-任务通知单编号-设计任务-工时 | N1: 订单号 | O1: 是否国际 | Q1: 行标签 | R1: 最大值项:个人原始项目工时之和/h | S1: 胸卡号 | T1: 专业室 | U1: 项目简称 | V1: 订单号
A2: =ROW()-1 -> 1 | B2: 徐丽娜 | C2: =IFERROR(VLOOKUP(B2,[66]工程研发事业部人员名单!B:D,2,0),"") -> 50079 | D2: =IFERROR(VLOOKUP(B2,[66]工程研发事业部人员名单!B:D,3,0),"") -> 工程项目室 /适航工程室 | E2: 项目开发与管控 | F2: =G2+H2+I2+J2 -> 70 | I2: 70 | K2: PMO | L2: 项目管理 | M2: 8号设计（2025年）： 1.上报项目月工时。 2.统计每月工时发生汇总，差旅发生费用，成本归集。 3.内部及涉密信息导入导出。 4.审签出差报销。 5.跟踪8-1.1、8-1.2项目回款状态，提醒客户启动第三笔回款申请。 6.组织8-1.3项目减重合同中期评审报告及PPT的准备，组织客户预评审技术报告。 7.完成8-1.3项目减重合同及技术协议的签订。 8.准备8-1.3项目减重合同及技术协议外带及对外提供手续。 9.组织准备8-1.3项目减重合同免税申报材料（技术方案）。 10.组织陕飞某项目舱门、后机身设计外包技术方案的编制、参加其评审会。 | N2: =VLOOKUP(E2,订单号!B:C,2,0) -> #N/A | O2: =VLOOKUP(C2,领导干部!B:B,1,0) -> #N/A | Q2: 柴宝 | R2: 210 | S2: {=VLOOKUP(Q2&R2,IF({1,0},$B$2:$B$330&$F$2:$F$330,$C$2:$C$330),2,)} -> 51944 | T2: {=VLOOKUP(Q2&R2,IF({1,0},$B$2:$B$330&$F$2:$F$330,$D$2:$D$330),2,)} -> 强度室 | U2: {=VLOOKUP(Q2&R2,IF({1,0},$B$2:$B$330&$F$2:$F$330,$E$2:$E$330),2,)} -> C929设计（2025年上飞院） | V2: {=VLOOKUP(Q2&R2,IF({1,0},$B$2:$B$330&$F$2:$F$330,$N$2:$N$330),2,)} -> YZ40000415
A3: =ROW()-1 -> 2 | B3: 徐丽娜 | C3: =IFERROR(VLOOKUP(B3,[66]工程研发事业部人员名单!B:D,2,0),"") -> 50079 | D3: =IFERROR(VLOOKUP(B3,[66]工程研发事业部人员名单!B:D,3,0),"") -> 工程项目室 /适航工程室 | E3: 项目开发与管控 | F3: =G3+H3+I3+J3 -> 50 | I3: 50 | K3: PMO | L3: 项目管理 | M3: C919基本型设计（2025年上飞院）： 1.上报项目月工时。 2.统计每月工时发生汇总，差旅发生费用，成本归集。 3.审签出差报销。 4.交付物存储地址建立。 5.编制并跟踪任务分解计划，协调处理项目进展问题。 6.协调项目人力资源。 7.与客户沟通项目任务清单、推动项目CSDB录入文件计划及存在的问题、损伤容限报告编制计划进展。 8.与客户沟通项目合同签订情况。 9.编制文件审签封面并组织实施。 | N3: =VLOOKUP(E3,订单号!B:C,2,0) -> #N/A | O3: =VLOOKUP(C3,领导干部!B:B,1,0) -> #N/A | Q3: 陈杰 | R3: 155 | S3: {=VLOOKUP(Q3&R3,IF({1,0},$B$2:$B$330&$F$2:$F$330,$C$2:$C$330),2,)} -> 25600 | T3: {=VLOOKUP(Q3&R3,IF({1,0},$B$2:$B$330&$F$2:$F$330,$D$2:$D$330),2,)} -> 结构二室 | U3: {=VLOOKUP(Q3&R3,IF({1,0},$B$2:$B$330&$F$2:$F$330,$E$2:$E$330),2,)} -> WH1项目结构强度综合 | V3: {=VLOOKUP(Q3&R3,IF({1,0},$B$2:$B$330&$F$2:$F$330,$N$2:$N$330),2,)} -> YZ-RD202428
A4: =ROW()-1 -> 3 | B4: 耿璐璐 | C4: =IFERROR(VLOOKUP(B4,[66]工程研发事业部人员名单!B:D,2,0),"") -> 51405 | D4: =IFERROR(VLOOKUP(B4,[66]工程研发事业部人员名单!B:D,3,0),"") -> 工程项目室 /适航工程室 | E4: 项目开发与管控 | F4: =G4+H4+I4+J4 -> 115 | I4: 115 | K4: PMO | L4: 项目管理 | M4: 1）1号-1.4设计：跟进合同进展情况； 2）C919YJTD：跟进项目进展，协调后机身工时认定，跟进合同立项情况等； 3）11号设计：跟进合同签订流程，完成两轮电子采购平台报价，编写合同文本、谈判记录及报价单； 4）完成集成研发业务域设计评审流程图、绩效指标表、流程清单等编制； 5）完成事业部驾驶舱PPT更新及业务场景需求数据表填写； 6）完成PMA流程梳理及可行性分析ppt，协助完成PMA件研制与取证费用预算； 7）机房/涉密台账管理，资产明细表更新，完成二季度纸质秘密载体台账/光磁介质秘密载体台账上报，内部载体移交。 | N4: =VLOOKUP(E4,订单号!B:C,2,0) -> #N/A | O4: =VLOOKUP(C4,领导干部!B:B,1,0) -> #N/A | Q4: 陈坤 | R4: 140 | S4: {=VLOOKUP(Q4&R4,IF({1,0},$B$2:$B$330&$F$2:$F$330,$C$2:$C$330),2,)} -> 51576 | T4: {=VLOOKUP(Q4&R4,IF({1,0},$B$2:$B$330&$F$2:$F$330,$D$2:$D$330),2,)} -> 联络工程室 | U4: {=VLOOKUP(Q4&R4,IF({1,0},$B$2:$B$330&$F$2:$F$330,$E$2:$E$330),2,)} -> 工程支持 | V4: {=VLOOKUP(Q4&R4,IF({1,0},$B$2:$B$330&$F$2:$F$330,$N$2:$N$330),2,)} -> 10502
A5: =ROW()-1 -> 4 | B5: 石荣荣 | C5: =IFERROR(VLOOKUP(B5,[66]工程研发事业部人员名单!B:D,2,0),"") -> 51166 | D5: =IFERROR(VLOOKUP(B5,[66]工程研发事业部人员名单!B:D,3,0),"") -> 工程项目室 /适航工程室 | E5: 项目开发与管控 | F5: =G5+H5+I5+J5 -> 150 | I5: 150 | K5: PMO | L5: 项目管理 | M5: 参加项目总师例会并作会议概要; 沟通协调我方和沈阳所工作衔接和人员衔接工作,协调已经入所人员安装软件解决电脑问题等工作; 梳理项目退所人员名单,组织填写退所手续,梳理退所所需机器号和key信息及收集蓝色工作证; 解决办公环境、生活(饭卡喝咖啡)等问题 完成6号-5项目，通过沈阳所结构部门内部预验收，组织完成项目交付物的准备及签字盖章 完成6号-5项目，通过沈阳所项目验收，并根据项目主管意见，组织完成项目交付物的整改及签字盖章 完成我公司在沈阳所供应商管理系统内资格解冻协调工作，并准备供应商整改资料 | N5: =VLOOKUP(E5,订单号!B:C,2,0) -> #N/A | O5: =VLOOKUP(C5,领导干部!B:B,1,0) -> #N/A | Q5: 陈磊 | R5: 170 | S5: {=VLOOKUP(Q5&R5,IF({1,0},$B$2:$B$330&$F$2:$F$330,$C$2:$C$330),2,)} -> 52180 | T5: {=VLOOKUP(Q5&R5,IF({1,0},$B$2:$B$330&$F$2:$F$330,$D$2:$D$330),2,)} -> 结构一室 | U5: {=VLOOKUP(Q5&R5,IF({1,0},$B$2:$B$330&$F$2:$F$330,$E$2:$E$330),2,)} -> C929设计（2025年上飞院） | V5: {=VLOOKUP(Q5&R5,IF({1,0},$B$2:$B$330&$F$2:$F$330,$N$2:$N$330),2,)} -> YZ40000415
A6: =ROW()-1 -> 5 | B6: 夏新鑫 | C6: =IFERROR(VLOOKUP(B6,[66]工程研发事业部人员名单!B:D,2,0),"") -> 50876 | D6: =IFERROR(VLOOKUP(B6,[66]工程研发事业部人员名单!B:D,3,0),"") -> 工程项目室 /适航工程室 | E6: 项目开发与管控 | F6: =G6+H6+I6+J6 -> 58 | I6: 58 | K6: PMO | L6: 项目管理 | M6: 完成商飞上岗培训框架协议合同签订；组织参加C929舱门周例会、月度汇报会；组织更新结构、强度专业用检查单等 | N6: =VLOOKUP(E6,订单号!B:C,2,0) -> #N/A | O6: =VLOOKUP(C6,领导干部!B:B,1,0) -> #N/A | Q6: 陈瑞东 | R6: 220 | S6: {=VLOOKUP(Q6&R6,IF({1,0},$B$2:$B$330&$F$2:$F$330,$C$2:$C$330),2,)} -> 51181 | T6: {=VLOOKUP(Q6&R6,IF({1,0},$B$2:$B$330&$F$2:$F$330,$D$2:$D$330),2,)} -> 强度室 | U6: {=VLOOKUP(Q6&R6,IF({1,0},$B$2:$B$330&$F$2:$F$330,$E$2:$E$330),2,)} -> C929设计（2025年上飞院） | V6: {=VLOOKUP(Q6&R6,IF({1,0},$B$2:$B$330&$F$2:$F$330,$N$2:$N$330),2,)} -> YZ40000415
A7: =ROW()-1 -> 6 | B7: 夏新鑫 | C7: =IFERROR(VLOOKUP(B7,[66]工程研发事业部人员名单!B:D,2,0),"") -> 50876 | D7: =IFERROR(VLOOKUP(B7,[66]工程研发事业部人员名单!B:D,3,0),"") -> 工程项目室 /适航工程室 | E7: 项目开发与管控 | F7: =G7+H7+I7+J7 -> 60 | I7: 60 | K7: PMO | L7: 项目管理 | M7: 组织参加C929垂尾、平尾周例会；完成复材中心验收评审补充工作并开具发票；沟通对接复材中心年度工作计划；组织更新结构、强度专业用检查单等 | N7: =VLOOKUP(E7,订单号!B:C,2,0) -> #N/A | O7: =VLOOKUP(C7,领导干部!B:B,1,0) -> #N/A | Q7: 晨曦 | R7: 98 | S7: {=VLOOKUP(Q7&R7,IF({1,0},$B$2:$B$330&$F$2:$F$330,$C$2:$C$330),2,)} -> 50030 | T7: {=VLOOKUP(Q7&R7,IF({1,0},$B$2:$B$330&$F$2:$F$330,$D$2:$D$330),2,)} -> 强度室 | U7: {=VLOOKUP(Q7&R7,IF({1,0},$B$2:$B$330&$F$2:$F$330,$E$2:$E$330),2,)} -> C919基本型设计（2025年上飞院） | V7: {=VLOOKUP(Q7&R7,IF({1,0},$B$2:$B$330&$F$2:$F$330,$N$2:$N$330),2,)} -> YZ40000419
A8: =ROW()-1 -> 7 | B8: 夏新鑫 | C8: =IFERROR(VLOOKUP(B8,[66]工程研发事业部人员名单!B:D,2,0),"") -> 50876 | D8: =IFERROR(VLOOKUP(B8,[66]工程研发事业部人员名单!B:D,3,0),"") -> 工程项目室 /适航工程室 | E8: 项目开发与管控 | F8: =G8+H8+I8+J8 -> 10 | I8: 10 | K8: PMO | L8: 项目管理 | M8: 沟通合同、设计输入、工作电脑等 | N8: =VLOOKUP(E8,订单号!B:C,2,0) -> #N/A | O8: =VLOOKUP(C8,领导干部!B:B,1,0) -> #N/A | Q8: 褚永鑫 | R8: 189 | S8: {=VLOOKUP(Q8&R8,IF({1,0},$B$2:$B$330&$F$2:$F$330,$C$2:$C$330),2,)} -> 22253 | T8: {=VLOOKUP(Q8&R8,IF({1,0},$B$2:$B$330&$F$2:$F$330,$D$2:$D$330),2,)} -> 联络工程室 | U8: {=VLOOKUP(Q8&R8,IF({1,0},$B$2:$B$330&$F$2:$F$330,$E$2:$E$330),2,)} -> 工程支持 | V8: {=VLOOKUP(Q8&R8,IF({1,0},$B$2:$B$330&$F$2:$F$330,$N$2:$N$330),2,)} -> 10502
A9: =ROW()-1 -> 8 | B9: 费天行 | C9: =IFERROR(VLOOKUP(B9,[66]工程研发事业部人员名单!B:D,2,0),"") -> 52570 | D9: =IFERROR(VLOOKUP(B9,[66]工程研发事业部人员名单!B:D,3,0),"") -> 工程项目室 /适航工程室 | E9: 项目开发与管控 | F9: =G9+H9+I9+J9 -> 30 | I9: 30 | K9: PMO | L9: 项目管理 | M9: 1.与甲方讨论商定技术协议的文本，项目的工作条目与工时量，跟踪进展 2.实时更新输入清单，记录工作交流过程 | N9: =VLOOKUP(E9,订单号!B:C,2,0) -> #N/A | O9: =VLOOKUP(C9,领导干部!B:B,1,0) -> #N/A | Q9: 丛家勇 | R9: 235 | S9: {=VLOOKUP(Q9&R9,IF({1,0},$B$2:$B$330&$F$2:$F$330,$C$2:$C$330),2,)} -> 50281 | T9: {=VLOOKUP(Q9&R9,IF({1,0},$B$2:$B$330&$F$2:$F$330,$D$2:$D$330),2,)} -> 结构一室 | U9: {=VLOOKUP(Q9&R9,IF({1,0},$B$2:$B$330&$F$2:$F$330,$E$2:$E$330),2,)} -> C929设计（2025年上飞院） | V9: {=VLOOKUP(Q9&R9,IF({1,0},$B$2:$B$330&$F$2:$F$330,$N$2:$N$330),2,)} -> YZ40000415
A10: =ROW()-1 -> 9 | B10: 费天行 | C10: =IFERROR(VLOOKUP(B10,[66]工程研发事业部人员名单!B:D,2,0),"") -> 52570 | D10: =IFERROR(VLOOKUP(B10,[66]工程研发事业部人员名单!B:D,3,0),"") -> 工程项目室 /适航工程室 | E10: 项目开发与管控 | F10: =G10+H10+I10+J10 -> 10 | I10: 10 | K10: PMO | L10: 项目管理 | M10: 1.跟踪甲方合同签订情况，项目进展 2.整理并和甲方确认结构识别工作量，形成验收单 | N10: =VLOOKUP(E10,订单号!B:C,2,0) -> #N/A | O10: =VLOOKUP(C10,领导干部!B:B,1,0) -> #N/A | Q10: 董晓莉 | R10: 155 | S10: {=VLOOKUP(Q10&R10,IF({1,0},$B$2:$B$330&$F$2:$F$330,$C$2:$C$330),2,)} -> 51211 | T10: {=VLOOKUP(Q10&R10,IF({1,0},$B$2:$B$330&$F$2:$F$330,$D$2:$D$330),2,)} -> 结构一室 | U10: {=VLOOKUP(Q10&R10,IF({1,0},$B$2:$B$330&$F$2:$F$330,$E$2:$E$330),2,)} -> WH1项目结构强度综合 | V10: {=VLOOKUP(Q10&R10,IF({1,0},$B$2:$B$330&$F$2:$F$330,$N$2:$N$330),2,)} -> YZ-RD202428
A11: =ROW()-1 -> 10 | B11: 徐丽娜 | C11: =IFERROR(VLOOKUP(B11,[66]工程研发事业部人员名单!B:D,2,0),"") -> 50079 | D11: =IFERROR(VLOOKUP(B11,[66]工程研发事业部人员名单!B:D,3,0),"") -> 工程项目室 /适航工程室 | E11: WH1项目总体/系统/适航等其它专业 | F11: =G11+H11+I11+J11 -> 30 | I11: 30 | K11: 适航 | M11: 无人机： 1.学习《高风险货运固定翼无人机系统适航标准》,审定基础（CB）初步梳理审核方法，梳理TP500型、UY-100 、翼龙-2气象型无人专用条件,梳理HY1701-HY1913章节 地址：\\192.168.10.140\newnas\data\yanfadata\WH1项目结构强度综合\05 其他工作包\14=适航管理\6月 | N11: =VLOOKUP(E11,订单号!B:C,2,0) -> YZ-RD202428 | O11: =VLOOKUP(C11,领导干部!B:B,1,0) -> #N/A | Q11: 杜洪雨 | R11: 220 | S11: {=VLOOKUP(Q11&R11,IF({1,0},$B$2:$B$330&$F$2:$F$330,$C$2:$C$330),2,)} -> 51170 | T11: {=VLOOKUP(Q11&R11,IF({1,0},$B$2:$B$330&$F$2:$F$330,$D$2:$D$330),2,)} -> 结构二室 | U11: {=VLOOKUP(Q11&R11,IF({1,0},$B$2:$B$330&$F$2:$F$330,$E$2:$E$330),2,)} -> C929设计（2025年上飞院） | V11: {=VLOOKUP(Q11&R11,IF({1,0},$B$2:$B$330&$F$2:$F$330,$N$2:$N$330),2,)} -> YZ40000415
A12: =ROW()-1 -> 11 | B12: 夏新鑫 | C12: =IFERROR(VLOOKUP(B12,[66]工程研发事业部人员名单!B:D,2,0),"") -> 50876 | D12: =IFERROR(VLOOKUP(B12,[66]工程研发事业部人员名单!B:D,3,0),"") -> 工程项目室 /适航工程室 | E12: WH1项目总体/系统/适航等其它专业 | F12: =G12+H12+I12+J12 -> 32 | I12: 32 | K12: 适航 | M12: 适航审定基础学习，交付物地址： \\192.168.10.140\newnas\data\yanfadata\WH1项目结构强度综合\05 其他工作包\14=适航管理\6月 | N12: =VLOOKUP(E12,订单号!B:C,2,0) -> YZ-RD202428 | O12: =VLOOKUP(C12,领导干部!B:B,1,0) -> #N/A | Q12: 付强 | R12: 164.88 | S12: {=VLOOKUP(Q12&R12,IF({1,0},$B$2:$B$330&$F$2:$F$330,$C$2:$C$330),2,)} -> 25549 | T12: {=VLOOKUP(Q12&R12,IF({1,0},$B$2:$B$330&$F$2:$F$330,$D$2:$D$330),2,)} -> 联络工程室 | U12: {=VLOOKUP(Q12&R12,IF({1,0},$B$2:$B$330&$F$2:$F$330,$E$2:$E$330),2,)} -> 工程支持 | V12: {=VLOOKUP(Q12&R12,IF({1,0},$B$2:$B$330&$F$2:$F$330,$N$2:$N$330),2,)} -> 10502
A13: =ROW()-1 -> 12 | B13: 石荣荣 | C13: =IFERROR(VLOOKUP(B13,[66]工程研发事业部人员名单!B:D,2,0),"") -> 51166 | D13: =IFERROR(VLOOKUP(B13,[66]工程研发事业部人员名单!B:D,3,0),"") -> 工程项目室 /适航工程室 | E13: WH1项目总体/系统/适航等其它专业 | F13: =G13+H13+I13+J13 -> 57 | I13: 57 | K13: 适航 | M13: 梳理适航条款，参加适航讨论会交付物在公共区\\192.168.10.140\newnas\data\yanfadata\WH1项目结构强度综合\05 其他工作包\14=适航管理\6月 | N13: =VLOOKUP(E13,订单号!B:C,2,0) -> YZ-RD202428 | O13: =VLOOKUP(C13,领导干部!B:B,1,0) -> #N/A | Q13: 付泉铭 | R13: 200 | S13: {=VLOOKUP(Q13&R13,IF({1,0},$B$2:$B$330&$F$2:$F$330,$C$2:$C$330),2,)} -> 51555 | T13: {=VLOOKUP(Q13&R13,IF({1,0},$B$2:$B$330&$F$2:$F$330,$D$2:$D$330),2,)} -> 联络工程室 | U13: {=VLOOKUP(Q13&R13,IF({1,0},$B$2:$B$330&$F$2:$F$330,$E$2:$E$330),2,)} -> SIA无人机设计-2 | V13: {=VLOOKUP(Q13&R13,IF({1,0},$B$2:$B$330&$F$2:$F$330,$N$2:$N$330),2,)} -> YZ40000422
A14: =ROW()-1 -> 13 | B14: 费天行 | C14: =IFERROR(VLOOKUP(B14,[66]工程研发事业部人员名单!B:D,2,0),"") -> 52570 | D14: =IFERROR(VLOOKUP(B14,[66]工程研发事业部人员名单!B:D,3,0),"") -> 工程项目室 /适航工程室 | E14: WH1项目总体/系统/适航等其它专业 | F14: =G14+H14+I14+J14 -> 60 | I14: 60 | K14: 适航 | M14: 讨论并编写审定基础，补充无人机专用条件与条款负责人专业，交付物已经放 \\192.168.10.140\newnas\data\yanfadata\WH1项目结构强度综合\05 其他工作包\14=适航管理\6月 | N14: =VLOOKUP(E14,订单号!B:C,2,0) -> YZ-RD202428 | O14: =VLOOKUP(C14,领导干部!B:B,1,0) -> #N/A | Q14: 付容容 | R14: 190 | S14: {=VLOOKUP(Q14&R14,IF({1,0},$B$2:$B$330&$F$2:$F$330,$C$2:$C$330),2,)} -> 51183 | T14: {=VLOOKUP(Q14&R14,IF({1,0},$B$2:$B$330&$F$2:$F$330,$D$2:$D$330),2,)} -> 结构一室 | U14: {=VLOOKUP(Q14&R14,IF({1,0},$B$2:$B$330&$F$2:$F$330,$E$2:$E$330),2,)} -> C929设计（2025年上飞院） | V14: {=VLOOKUP(Q14&R14,IF({1,0},$B$2:$B$330&$F$2:$F$330,$N$2:$N$330),2,)} -> YZ40000415
A15: =ROW()-1 -> 14 | B15: 耿璐璐 | C15: =IFERROR(VLOOKUP(B15,[66]工程研发事业部人员名单!B:D,2,0),"") -> 51405 | D15: =IFERROR(VLOOKUP(B15,[66]工程研发事业部人员名单!B:D,3,0),"") -> 工程项目室 /适航工程室 | E15: WH1项目总体/系统/适航等其它专业 | F15: =G15+H15+I15+J15 -> 30 | I15: 30 | K15: 适航 | M15: 大型固定翼货运无人机系统适航审定基础梳理，燃油、滑油、进排气系统适航条款研究，参加讨论会；适航学习交付物存放地址： \\192.168.10.140\newnas\data\yanfadata\WH1项目结构强度综合\05 其他工作包\14=适航管理 | N15: =VLOOKUP(E15,订单号!B:C,2,0) -> YZ-RD202428 | O15: =VLOOKUP(C15,领导干部!B:B,1,0) -> #N/A | Q15: 高秉芳 | R15: 166.68 | S15: {=VLOOKUP(Q15&R15,IF({1,0},$B$2:$B$330&$F$2:$F$330,$C$2:$C$330),2,)} -> 26688 | T15: {=VLOOKUP(Q15&R15,IF({1,0},$B$2:$B$330&$F$2:$F$330,$D$2:$D$330),2,)} -> 联络工程室 | U15: {=VLOOKUP(Q15&R15,IF({1,0},$B$2:$B$330&$F$2:$F$330,$E$2:$E$330),2,)} -> 工程支持 | V15: {=VLOOKUP(Q15&R15,IF({1,0},$B$2:$B$330&$F$2:$F$330,$N$2:$N$330),2,)} -> 10502
A16: =ROW()-1 -> 15 | B16: 吕冬兰 | C16: =IFERROR(VLOOKUP(B16,[66]工程研发事业部人员名单!B:D,2,0),"") -> 51160 | D16: =IFERROR(VLOOKUP(B16,[66]工程研发事业部人员名单!B:D,3,0),"") -> 综合技术室 | E16: 重点工作任务 | F16: =G16+H16+I16+J16 -> 15 | I16: 15 | K16: 材料及工艺 | L16: 贯彻民用航空高质量发展三年行动方案任务 | M16: 联系供应链和质量部获取试验项目报价，联系物流中心获取质保单和理化试验报告及库存量核实，联系采购部门询问材料价格，计算原材料价格 | N16: =VLOOKUP(E16,订单号!B:C,2,0) -> 0 | O16: =VLOOKUP(C16,领导干部!B:B,1,0) -> #N/A | Q16: 高奇 | R16: 157 | S16: {=VLOOKUP(Q16&R16,IF({1,0},$B$2:$B$330&$F$2:$F$330,$C$2:$C$330),2,)} -> 17732 | T16: {=VLOOKUP(Q16&R16,IF({1,0},$B$2:$B$330&$F$2:$F$330,$D$2:$D$330),2,)} -> 联络工程室 | U16: {=VLOOKUP(Q16&R16,IF({1,0},$B$2:$B$330&$F$2:$F$330,$E$2:$E$330),2,)} -> 工程支持 | V16: {=VLOOKUP(Q16&R16,IF({1,0},$B$2:$B$330&$F$2:$F$330,$N$2:$N$330),2,)} -> 10502
A17: =ROW()-1 -> 16 | B17: 朱海 | C17: =IFERROR(VLOOKUP(B17,[66]工程研发事业部人员名单!B:D,2,0),"") -> 52232 | D17: =IFERROR(VLOOKUP(B17,[66]工程研发事业部人员名单!B:D,3,0),"") -> 结构二室 | E17: 重点工作任务 | F17: =G17+H17+I17+J17 -> 48 | I17: 48 | K17: 结构 | L17: 贯彻民用航空高质量发展三年行动方案任务 | M17: 1.学习CATIA逆向工程曲面设计方法； 2.搜寻B737零件图纸。 | N17: =VLOOKUP(E17,订单号!B:C,2,0) -> 0 | O17: =VLOOKUP(C17,领导干部!B:B,1,0) -> #N/A | Q17: 葛春生 | R17: 120 | S17: {=VLOOKUP(Q17&R17,IF({1,0},$B$2:$B$330&$F$2:$F$330,$C$2:$C$330),2,)} -> 51410 | T17: {=VLOOKUP(Q17&R17,IF({1,0},$B$2:$B$330&$F$2:$F$330,$D$2:$D$330),2,)} -> 结构一室 | U17: {=VLOOKUP(Q17&R17,IF({1,0},$B$2:$B$330&$F$2:$F$330,$E$2:$E$330),2,)} -> WH1项目结构强度综合 | V17: {=VLOOKUP(Q17&R17,IF({1,0},$B$2:$B$330&$F$2:$F$330,$N$2:$N$330),2,)} -> YZ-RD202428
A18: =ROW()-1 -> 17 | B18: 孙永光 | C18: =IFERROR(VLOOKUP(B18,[66]工程研发事业部人员名单!B:D,2,0),"") -> 25601 | D18: =IFERROR(VLOOKUP(B18,[66]工程研发事业部人员名单!B:D,3,0),"") -> 联络工程室 | E18: 重点工作任务 | F18: =G18+H18+I18+J18 -> 48 | I18: 48 | K18: 结构 | L18: 贯彻民用航空高质量发展三年行动方案任务 | M18: 1.学习CATIA逆向工程曲面设计方法； 2.搜寻B737零件图纸。 | N18: =VLOOKUP(E18,订单号!B:C,2,0) -> 0 | O18: =VLOOKUP(C18,领导干部!B:B,1,0) -> #N/A | Q18: 耿璐璐 | R18: 115 | S18: {=VLOOKUP(Q18&R18,IF({1,0},$B$2:$B$330&$F$2:$F$330,$C$2:$C$330),2,)} -> 51405 | T18: {=VLOOKUP(Q18&R18,IF({1,0},$B$2:$B$330&$F$2:$F$330,$D$2:$D$330),2,)} -> 工程项目室 /适航工程室 | U18: {=VLOOKUP(Q18&R18,IF({1,0},$B$2:$B$330&$F$2:$F$330,$E$2:$E$330),2,)} -> 项目开发与管控 | V18: {=VLOOKUP(Q18&R18,IF({1,0},$B$2:$B$330&$F$2:$F$330,$N$2:$N$330),2,)} -> #N/A
A19: =ROW()-1 -> 18 | B19: 王健 | C19: =IFERROR(VLOOKUP(B19,[66]工程研发事业部人员名单!B:D,2,0),"") -> 51784 | D19: =IFERROR(VLOOKUP(B19,[66]工程研发事业部人员名单!B:D,3,0),"") -> 结构一室 | E19: 重点工作任务 | F19: =G19+H19+I19+J19 -> 7.5 | I19: 7.5 | K19: 结构 | L19: 贯彻民用航空高质量发展三年行动方案任务 | M19: 1、参加PMA取证讨论会； 2、协助完成PMA件费用测算。 | N19: =VLOOKUP(E19,订单号!B:C,2,0) -> 0 | O19: =VLOOKUP(C19,领导干部!B:B,1,0) -> #N/A | Q19: 郭静 | R19: 150.2 | S19: {=VLOOKUP(Q19&R19,IF({1,0},$B$2:$B$330&$F$2:$F$330,$C$2:$C$330),2,)} -> 50027 | T19: {=VLOOKUP(Q19&R19,IF({1,0},$B$2:$B$330&$F$2:$F$330,$D$2:$D$330),2,)} -> 联络工程室 | U19: {=VLOOKUP(Q19&R19,IF({1,0},$B$2:$B$330&$F$2:$F$330,$E$2:$E$330),2,)} -> 工程支持 | V19: {=VLOOKUP(Q19&R19,IF({1,0},$B$2:$B$330&$F$2:$F$330,$N$2:$N$330),2,)} -> 10502
A20: =ROW()-1 -> 19 | B20: 魏士礼 | C20: =IFERROR(VLOOKUP(B20,[66]工程研发事业部人员名单!B:D,2,0),"") -> 22294 | D20: =IFERROR(VLOOKUP(B20,[66]工程研发事业部人员名单!B:D,3,0),"") -> 结构一室 | E20: 8号-1.3设计 | F20: =G20+H20+I20+J20 -> 10 | I20: 10 | K20: 结构 | L20: 8号垂尾优化设计 | M20: 8-1.3垂尾中期评审报告和交付物优化 | N20: =VLOOKUP(E20,订单号!B:C,2,0) -> YZ40000414 | O20: =VLOOKUP(C20,领导干部!B:B,1,0) -> #N/A | Q20: 郭晓庆 | R20: 220 | S20: {=VLOOKUP(Q20&R20,IF({1,0},$B$2:$B$330&$F$2:$F$330,$C$2:$C$330),2,)} -> 50275 | T20: {=VLOOKUP(Q20&R20,IF({1,0},$B$2:$B$330&$F$2:$F$330,$D$2:$D$330),2,)} -> 结构一室 | U20: {=VLOOKUP(Q20&R20,IF({1,0},$B$2:$B$330&$F$2:$F$330,$E$2:$E$330),2,)} -> C929设计（2025年上飞院） | V20: {=VLOOKUP(Q20&R20,IF({1,0},$B$2:$B$330&$F$2:$F$330,$N$2:$N$330),2,)} -> YZ40000415
A21: =ROW()-1 -> 20 | B21: 杨春 | C21: =IFERROR(VLOOKUP(B21,[66]工程研发事业部人员名单!B:D,2,0),"") -> 51624 | D21: =IFERROR(VLOOKUP(B21,[66]工程研发事业部人员名单!B:D,3,0),"") -> 结构一室 | E21: 8号-1.3设计 | F21: =G21+H21+I21+J21 -> 2 | I21: 2 | K21: 结构 | L21: 8号垂尾优化设计 | M21: 8-1.3垂尾中期评审报告优化和交付物校对 | N21: =VLOOKUP(E21,订单号!B:C,2,0) -> YZ40000414 | O21: =VLOOKUP(C21,领导干部!B:B,1,0) -> #N/A | Q21: 何续斌 | R21: 190 | S21: {=VLOOKUP(Q21&R21,IF({1,0},$B$2:$B$330&$F$2:$F$330,$C$2:$C$330),2,)} -> 50871 | T21: {=VLOOKUP(Q21&R21,IF({1,0},$B$2:$B$330&$F$2:$F$330,$D$2:$D$330),2,)} -> 强度室 | U21: {=VLOOKUP(Q21&R21,IF({1,0},$B$2:$B$330&$F$2:$F$330,$E$2:$E$330),2,)} -> WH1项目结构强度综合 | V21: {=VLOOKUP(Q21&R21,IF({1,0},$B$2:$B$330&$F$2:$F$330,$N$2:$N$330),2,)} -> YZ-RD202428
A22: =ROW()-1 -> 21 | B22: 孟祥瑞 | C22: =IFERROR(VLOOKUP(B22,[66]工程研发事业部人员名单!B:D,2,0),"") -> 51615 | D22: =IFERROR(VLOOKUP(B22,[66]工程研发事业部人员名单!B:D,3,0),"") -> 结构一室 | E22: 8号-1.3设计 | F22: =G22+H22+I22+J22 -> 2 | I22: 2 | K22: 结构 | L22: 8号垂尾优化设计 | M22: 8-1.3垂尾中期评审报告优化和交付物校对 | N22: =VLOOKUP(E22,订单号!B:C,2,0) -> YZ40000414 | O22: =VLOOKUP(C22,领导干部!B:B,1,0) -> #N/A | Q22: 霍东旭 | R22: 180 | S22: {=VLOOKUP(Q22&R22,IF({1,0},$B$2:$B$330&$F$2:$F$330,$C$2:$C$330),2,)} -> 51941 | T22: {=VLOOKUP(Q22&R22,IF({1,0},$B$2:$B$330&$F$2:$F$330,$D$2:$D$330),2,)} -> 联络工程室 | U22: {=VLOOKUP(Q22&R22,IF({1,0},$B$2:$B$330&$F$2:$F$330,$E$2:$E$330),2,)} -> C919高原型设计（2025年上飞院） | V22: {=VLOOKUP(Q22&R22,IF({1,0},$B$2:$B$330&$F$2:$F$330,$N$2:$N$330),2,)} -> YZ40000417
A23: =ROW()-1 -> 22 | B23: 马岩 | C23: =IFERROR(VLOOKUP(B23,[66]工程研发事业部人员名单!B:D,2,0),"") -> 50730 | D23: =IFERROR(VLOOKUP(B23,[66]工程研发事业部人员名单!B:D,3,0),"") -> 结构一室 | E23: 8号-1.3设计 | F23: =G23+H23+I23+J23 -> 25 | J23: 25 | K23: 结构 | L23: 8号垂尾优化设计 | M23: 8号舱门及减重合同： 1.出差去汉中送减重合同 2.协助陕飞解决复材舱门问题、登机门安装调整问题 3.协助陕飞处理试验规划相关问题 | N23: =VLOOKUP(E23,订单号!B:C,2,0) -> YZ40000414 | O23: =VLOOKUP(C23,领导干部!B:B,1,0) -> #N/A | Q23: 纪可 | R23: 190 | S23: {=VLOOKUP(Q23&R23,IF({1,0},$B$2:$B$330&$F$2:$F$330,$C$2:$C$330),2,)} -> 26689 | T23: {=VLOOKUP(Q23&R23,IF({1,0},$B$2:$B$330&$F$2:$F$330,$D$2:$D$330),2,)} -> 强度室 | U23: {=VLOOKUP(Q23&R23,IF({1,0},$B$2:$B$330&$F$2:$F$330,$E$2:$E$330),2,)} -> C929设计（2025年上飞院） | V23: {=VLOOKUP(Q23&R23,IF({1,0},$B$2:$B$330&$F$2:$F$330,$N$2:$N$330),2,)} -> YZ40000415
A24: =ROW()-1 -> 23 | B24: 郑石 | C24: =IFERROR(VLOOKUP(B24,[66]工程研发事业部人员名单!B:D,2,0),"") -> 26766 | D24: =IFERROR(VLOOKUP(B24,[66]工程研发事业部人员名单!B:D,3,0),"") -> 强度室 | E24: C919YJTD设计 | F24: =G24+H24+I24+J24 -> 60 | I24: 60 | K24: 强度 | L24: 垂尾 | M24: 1.垂尾虚拟试验件根部接头垂向载荷对比分析，肋剖面载荷对比分析 2.垂尾试验件73框位置两种优化方案与原DFEM模型的垂向根部载荷对比 | N24: =VLOOKUP(E24,订单号!B:C,2,0) -> YZ40000410 | O24: =VLOOKUP(C24,领导干部!B:B,1,0) -> #N/A | Q24: 贾永亮 | R24: 180 | S24: {=VLOOKUP(Q24&R24,IF({1,0},$B$2:$B$330&$F$2:$F$330,$C$2:$C$330),2,)} -> 52131 | T24: {=VLOOKUP(Q24&R24,IF({1,0},$B$2:$B$330&$F$2:$F$330,$D$2:$D$330),2,)} -> 结构二室 | U24: {=VLOOKUP(Q24&R24,IF({1,0},$B$2:$B$330&$F$2:$F$330,$E$2:$E$330),2,)} -> C929设计（2025年上飞院） | V24: {=VLOOKUP(Q24&R24,IF({1,0},$B$2:$B$330&$F$2:$F$330,$N$2:$N$330),2,)} -> YZ40000415
A25: =ROW()-1 -> 24 | B25: 晨曦 | C25: =IFERROR(VLOOKUP(B25,[66]工程研发事业部人员名单!B:D,2,0),"") -> 50030 | D25: =IFERROR(VLOOKUP(B25,[66]工程研发事业部人员名单!B:D,3,0),"") -> 强度室 | E25: C919YJTD设计 | F25: =G25+H25+I25+J25 -> 92 | I25: 92 | K25: 强度 | L25: 垂尾 | M25: 1.垂尾根部试验件细节有限元模型建模 2.垂尾根部试验件加载、边界约束、试算。根部接头载荷对比与问题分析。 3.垂尾虚拟试验件方案二有限元模型修改与试算。 | N25: =VLOOKUP(E25,订单号!B:C,2,0) -> YZ40000410 | O25: =VLOOKUP(C25,领导干部!B:B,1,0) -> #N/A | Q25: 焦凯 | R25: 170 | S25: {=VLOOKUP(Q25&R25,IF({1,0},$B$2:$B$330&$F$2:$F$330,$C$2:$C$330),2,)} -> 52342 | T25: {=VLOOKUP(Q25&R25,IF({1,0},$B$2:$B$330&$F$2:$F$330,$D$2:$D$330),2,)} -> 强度室 | U25: {=VLOOKUP(Q25&R25,IF({1,0},$B$2:$B$330&$F$2:$F$330,$E$2:$E$330),2,)} -> WH1项目结构强度综合 | V25: {=VLOOKUP(Q25&R25,IF({1,0},$B$2:$B$330&$F$2:$F$330,$N$2:$N$330),2,)} -> YZ-RD202428
A26: =ROW()-1 -> 25 | B26: 郑石 | C26: =IFERROR(VLOOKUP(B26,[66]工程研发事业部人员名单!B:D,2,0),"") -> 26766 | D26: =IFERROR(VLOOKUP(B26,[66]工程研发事业部人员名单!B:D,3,0),"") -> 强度室 | E26: C919YJTD设计 | F26: =G26+H26+I26+J26 -> 20 | I26: 20 | K26: 强度 | L26: 后机身 | M26: 919后机身许用值更新，协调任务分配，校核分析结果，汇总裕度变化情况 | N26: =VLOOKUP(E26,订单号!B:C,2,0) -> YZ40000410 | O26: =VLOOKUP(C26,领导干部!B:B,1,0) -> #N/A | Q26: 靳海丰 | R26: 200 | S26: {=VLOOKUP(Q26&R26,IF({1,0},$B$2:$B$330&$F$2:$F$330,$C$2:$C$330),2,)} -> 51158 | T26: {=VLOOKUP(Q26&R26,IF({1,0},$B$2:$B$330&$F$2:$F$330,$D$2:$D$330),2,)} -> 强度室 | U26: {=VLOOKUP(Q26&R26,IF({1,0},$B$2:$B$330&$F$2:$F$330,$E$2:$E$330),2,)} -> C929设计（2025年上飞院） | V26: {=VLOOKUP(Q26&R26,IF({1,0},$B$2:$B$330&$F$2:$F$330,$N$2:$N$330),2,)} -> YZ40000415
A27: =ROW()-1 -> 26 | B27: 祝堃 | C27: =IFERROR(VLOOKUP(B27,[66]工程研发事业部人员名单!B:D,2,0),"") -> 52256 | D27: =IFERROR(VLOOKUP(B27,[66]工程研发事业部人员名单!B:D,3,0),"") -> 强度室 | E27: C919YJTD设计 | F27: =G27+H27+I27+J27 -> 10 | I27: 10 | K27: 强度 | L27: 后机身 | M27: 919后机身泄压报告前后段对接、后机身与中后机身对接、77-78框部分工具与报告内容校对 | N27: =VLOOKUP(E27,订单号!B:C,2,0) -> YZ40000410 | O27: =VLOOKUP(C27,领导干部!B:B,1,0) -> #N/A | Q27: 康霞 | R27: 125 | S27: {=VLOOKUP(Q27&R27,IF({1,0},$B$2:$B$330&$F$2:$F$330,$C$2:$C$330),2,)} -> 52132 | T27: {=VLOOKUP(Q27&R27,IF({1,0},$B$2:$B$330&$F$2:$F$330,$D$2:$D$330),2,)} -> 结构二室 | U27: {=VLOOKUP(Q27&R27,IF({1,0},$B$2:$B$330&$F$2:$F$330,$E$2:$E$330),2,)} -> SIA无人机设计-2 | V27: {=VLOOKUP(Q27&R27,IF({1,0},$B$2:$B$330&$F$2:$F$330,$N$2:$N$330),2,)} -> YZ40000422
A28: =ROW()-1 -> 27 | B28: 张文静 | C28: =IFERROR(VLOOKUP(B28,[66]工程研发事业部人员名单!B:D,2,0),"") -> 22259 | D28: =IFERROR(VLOOKUP(B28,[66]工程研发事业部人员名单!B:D,3,0),"") -> 强度室 | E28: C919YJTD设计 | F28: =G28+H28+I28+J28 -> 15 | I28: 15 | K28: 强度 | L28: 后机身 | M28: 919泄压报告球面框、平尾开口加强梁和74-76框部分工具与报告内容校核 | N28: =VLOOKUP(E28,订单号!B:C,2,0) -> YZ40000410 | O28: =VLOOKUP(C28,领导干部!B:B,1,0) -> #N/A | Q28: 康志明 | R28: 190 | S28: {=VLOOKUP(Q28&R28,IF({1,0},$B$2:$B$330&$F$2:$F$330,$C$2:$C$330),2,)} -> 25765 | T28: {=VLOOKUP(Q28&R28,IF({1,0},$B$2:$B$330&$F$2:$F$330,$D$2:$D$330),2,)} -> 结构一室 | U28: {=VLOOKUP(Q28&R28,IF({1,0},$B$2:$B$330&$F$2:$F$330,$E$2:$E$330),2,)} -> C929设计（2025年上飞院） | V28: {=VLOOKUP(Q28&R28,IF({1,0},$B$2:$B$330&$F$2:$F$330,$N$2:$N$330),2,)} -> YZ40000415
A29: =ROW()-1 -> 28 | B29: 刘媛媛 | C29: =IFERROR(VLOOKUP(B29,[66]工程研发事业部人员名单!B:D,2,0),"") -> 51385 | D29: =IFERROR(VLOOKUP(B29,[66]工程研发事业部人员名单!B:D,3,0),"") -> 系统室 | E29: C919YJTD设计 | F29: =G29+H29+I29+J29 -> 17.5 | I29: 17.5 | K29: 强度 | L29: 后机身 | M29: 919后机身许用值更新，77-78框拉压剪许用值受影响工具更新；挤压许用值受影响工具更新 | N29: =VLOOKUP(E29,订单号!B:C,2,0) -> YZ40000410 | O29: =VLOOKUP(C29,领导干部!B:B,1,0) -> #N/A | Q29: 李爱环 | R29: 200 | S29: {=VLOOKUP(Q29&R29,IF({1,0},$B$2:$B$330&$F$2:$F$330,$C$2:$C$330),2,)} -> 50726 | T29: {=VLOOKUP(Q29&R29,IF({1,0},$B$2:$B$330&$F$2:$F$330,$D$2:$D$330),2,)} -> 强度室 | U29: {=VLOOKUP(Q29&R29,IF({1,0},$B$2:$B$330&$F$2:$F$330,$E$2:$E$330),2,)} -> C929设计（2025年上飞院） | V29: {=VLOOKUP(Q29&R29,IF({1,0},$B$2:$B$330&$F$2:$F$330,$N$2:$N$330),2,)} -> YZ40000415
A30: =ROW()-1 -> 29 | B30: 宋凯 | C30: =IFERROR(VLOOKUP(B30,[66]工程研发事业部人员名单!B:D,2,0),"") -> 51951 | D30: =IFERROR(VLOOKUP(B30,[66]工程研发事业部人员名单!B:D,3,0),"") -> 系统室 | E30: C919YJTD设计 | F30: =G30+H30+I30+J30 -> 20 | I30: 20 | K30: 强度 | L30: 后机身 | M30: 919后机身许用值更新，74-76框拉压剪、拉脱和层间、挤压等许用值受影响的工具更新 | N30: =VLOOKUP(E30,订单号!B:C,2,0) -> YZ40000410 | O30: =VLOOKUP(C30,领导干部!B:B,1,0) -> #N/A | Q30: 李金鹰 | R30: 180 | S30: {=VLOOKUP(Q30&R30,IF({1,0},$B$2:$B$330&$F$2:$F$330,$C$2:$C$330),2,)} -> 51227 | T30: {=VLOOKUP(Q30&R30,IF({1,0},$B$2:$B$330&$F$2:$F$330,$D$2:$D$330),2,)} -> 结构一室 | U30: {=VLOOKUP(Q30&R30,IF({1,0},$B$2:$B$330&$F$2:$F$330,$E$2:$E$330),2,)} -> C929设计（2025年上飞院） | V30: {=VLOOKUP(Q30&R30,IF({1,0},$B$2:$B$330&$F$2:$F$330,$N$2:$N$330),2,)} -> YZ40000415
A31: =ROW()-1 -> 30 | B31: 任斌 | C31: =IFERROR(VLOOKUP(B31,[66]工程研发事业部人员名单!B:D,2,0),"") -> 51517 | D31: =IFERROR(VLOOKUP(B31,[66]工程研发事业部人员名单!B:D,3,0),"") -> 系统室 | E31: C919YJTD设计 | F31: =G31+H31+I31+J31 -> 6 | I31: 6 | K31: 强度 | L31: 后机身 | M31: 919后机身许用值更新，前后段对接和平尾开口加强梁结构挤压许用值受影响的工具更新 | N31: =VLOOKUP(E31,订单号!B:C,2,0) -> YZ40000410 | O31: =VLOOKUP(C31,领导干部!B:B,1,0) -> #N/A | Q31: 李其鹏 | R31: 70 | S31: {=VLOOKUP(Q31&R31,IF({1,0},$B$2:$B$330&$F$2:$F$330,$C$2:$C$330),2,)} -> 51429 | T31: {=VLOOKUP(Q31&R31,IF({1,0},$B$2:$B$330&$F$2:$F$330,$D$2:$D$330),2,)} -> 综合技术室 | U31: {=VLOOKUP(Q31&R31,IF({1,0},$B$2:$B$330&$F$2:$F$330,$E$2:$E$330),2,)} -> WH1项目结构强度综合 | V31: {=VLOOKUP(Q31&R31,IF({1,0},$B$2:$B$330&$F$2:$F$330,$N$2:$N$330),2,)} -> YZ-RD202428
A32: =ROW()-1 -> 31 | B32: 夏雷 | C32: =IFERROR(VLOOKUP(B32,[66]工程研发事业部人员名单!B:D,2,0),"") -> 52587 | D32: =IFERROR(VLOOKUP(B32,[66]工程研发事业部人员名单!B:D,3,0),"") -> 系统室 | E32: C919YJTD设计 | F32: =G32+H32+I32+J32 -> 20 | I32: 20 | K32: 强度 | L32: 后机身 | M32: 919后机身许用值更新，前段壁板拉压剪、拉脱和层间、挤压等许用值受影响的工具更新 | N32: =VLOOKUP(E32,订单号!B:C,2,0) -> YZ40000410 | O32: =VLOOKUP(C32,领导干部!B:B,1,0) -> #N/A | Q32: 李森 | R32: 135 | S32: {=VLOOKUP(Q32&R32,IF({1,0},$B$2:$B$330&$F$2:$F$330,$C$2:$C$330),2,)} -> 17238 | T32: {=VLOOKUP(Q32&R32,IF({1,0},$B$2:$B$330&$F$2:$F$330,$D$2:$D$330),2,)} -> 结构二室 | U32: {=VLOOKUP(Q32&R32,IF({1,0},$B$2:$B$330&$F$2:$F$330,$E$2:$E$330),2,)} -> WH1项目结构强度综合 | V32: {=VLOOKUP(Q32&R32,IF({1,0},$B$2:$B$330&$F$2:$F$330,$N$2:$N$330),2,)} -> YZ-RD202428
A33: =ROW()-1 -> 32 | B33: 赵子维 | C33: =IFERROR(VLOOKUP(B33,[66]工程研发事业部人员名单!B:D,2,0),"") -> 52585 | D33: =IFERROR(VLOOKUP(B33,[66]工程研发事业部人员名单!B:D,3,0),"") -> 系统室 | E33: C919YJTD设计 | F33: =G33+H33+I33+J33 -> 5.5 | I33: 5.5 | K33: 强度 | L33: 后机身 | M33: 919后机身许用值更新，平尾开口加强梁结构挤压许用值更新受影响工具更新 | N33: =VLOOKUP(E33,订单号!B:C,2,0) -> YZ40000410 | O33: =VLOOKUP(C33,领导干部!B:B,1,0) -> #N/A | Q33: 李守玺 | R33: 210 | S33: {=VLOOKUP(Q33&R33,IF({1,0},$B$2:$B$330&$F$2:$F$330,$C$2:$C$330),2,)} -> 25763 | T33: {=VLOOKUP(Q33&R33,IF({1,0},$B$2:$B$330&$F$2:$F$330,$D$2:$D$330),2,)} -> 结构一室 | U33: {=VLOOKUP(Q33&R33,IF({1,0},$B$2:$B$330&$F$2:$F$330,$E$2:$E$330),2,)} -> SIA无人机设计-2 | V33: {=VLOOKUP(Q33&R33,IF({1,0},$B$2:$B$330&$F$2:$F$330,$N$2:$N$330),2,)} -> YZ40000422
A34: =ROW()-1 -> 33 | B34: 魏春生 | C34: =IFERROR(VLOOKUP(B34,[66]工程研发事业部人员名单!B:D,2,0),"") -> 51389 | D34: =IFERROR(VLOOKUP(B34,[66]工程研发事业部人员名单!B:D,3,0),"") -> 系统室 | E34: C919YJTD设计 | F34: =G34+H34+I34+J34 -> 5.5 | I34: 5.5 | K34: 强度 | L34: 后机身 | M34: 919后机身许用值更新，后机身与中后机身对接挤压许用值更新受影响工具更新 | N34: =VLOOKUP(E34,订单号!B:C,2,0) -> YZ40000410 | O34: =VLOOKUP(C34,领导干部!B:B,1,0) -> #N/A | Q34: 李湘芝 | R34: 168.05 | S34: {=VLOOKUP(Q34&R34,IF({1,0},$B$2:$B$330&$F$2:$F$330,$C$2:$C$330),2,)} -> 50019 | T34: {=VLOOKUP(Q34&R34,IF({1,0},$B$2:$B$330&$F$2:$F$330,$D$2:$D$330),2,)} -> 联络工程室 | U34: {=VLOOKUP(Q34&R34,IF({1,0},$B$2:$B$330&$F$2:$F$330,$E$2:$E$330),2,)} -> 工程支持 | V34: {=VLOOKUP(Q34&R34,IF({1,0},$B$2:$B$330&$F$2:$F$330,$N$2:$N$330),2,)} -> 10502
A35: =ROW()-1 -> 34 | B35: 赵艳秦 | C35: =IFERROR(VLOOKUP(B35,[66]工程研发事业部人员名单!B:D,2,0),"") -> 50022 | D35: =IFERROR(VLOOKUP(B35,[66]工程研发事业部人员名单!B:D,3,0),"") -> 结构二室 | E35: C919YJTD设计 | F35: =G35+H35+I35+J35 -> 210 | I35: 210 | K35: 结构 | L35: 后机身/垂尾 | M35: 后机身组件P产数模注释更改，共计27个组件，多个零件设计更改，3个实验组件更改；垂尾新增加框根部试验件，PT20垂尾试验组件设计更改 | N35: =VLOOKUP(E35,订单号!B:C,2,0) -> YZ40000410 | O35: =VLOOKUP(C35,领导干部!B:B,1,0) -> #N/A | Q35: 李妍 | R35: 120 | S35: {=VLOOKUP(Q35&R35,IF({1,0},$B$2:$B$330&$F$2:$F$330,$C$2:$C$330),2,)} -> 51435 | T35: {=VLOOKUP(Q35&R35,IF({1,0},$B$2:$B$330&$F$2:$F$330,$D$2:$D$330),2,)} -> 系统室 | U35: {=VLOOKUP(Q35&R35,IF({1,0},$B$2:$B$330&$F$2:$F$330,$E$2:$E$330),2,)} -> C919基本型设计（2025年上飞院） | V35: {=VLOOKUP(Q35&R35,IF({1,0},$B$2:$B$330&$F$2:$F$330,$N$2:$N$330),2,)} -> YZ40000419
... A63: =ROW()-1 -> 62 | B63: 赵婷 | C63: =IFERROR(VLOOKUP(B63,[66]工程研发事业部人员名单!B:D,2,0),"") -> 50702 | D63: =IFERROR(VLOOKUP(B63,[66]工程研发事业部人员名单!B:D,3,0),"") -> 总体室 | E63: C919基本型设计（2025年上飞院） | F63: =G63+H63+I63+J63 -> 52 | I63: 52 | K63: 强度 | L63: C919手册2025年 | M63: 26份报告手册文件对比 | N63: =VLOOKUP(E63,订单号!B:C,2,0) -> YZ40000419 | O63: =VLOOKUP(C63,领导干部!B:B,1,0) -> #N/A | Q63: 孟玲俊 | R63: 120 | S63: {=VLOOKUP(Q63&R63,IF({1,0},$B$2:$B$330&$F$2:$F$330,$C$2:$C$330),2,)} -> 22298 | T63: {=VLOOKUP(Q63&R63,IF({1,0},$B$2:$B$330&$F$2:$F$330,$D$2:$D$330),2,)} -> 结构二室 | U63: {=VLOOKUP(Q63&R63,IF({1,0},$B$2:$B$330&$F$2:$F$330,$E$2:$E$330),2,)} -> C929设计（2025年上飞院） | V63: {=VLOOKUP(Q63&R63,IF({1,0},$B$2:$B$330&$F$2:$F$330,$N$2:$N$330),2,)} -> YZ40000415
A64: =ROW()-1 -> 63 | B64: 吴晓莉 | C64: =IFERROR(VLOOKUP(B64,[66]工程研发事业部人员名单!B:D,2,0),"") -> 50872 | D64: =IFERROR(VLOOKUP(B64,[66]工程研发事业部人员名单!B:D,3,0),"") -> 系统室 | E64: C919手册优化（2025年复材中心） | F64: =G64+H64+I64+J64 -> 91 | I64: 91 | K64: 系统 | M64: 1.1 CSDB三方线上会议一次-2h 1.2 CSDB三方线线上会议，问题梳理及对解答的整理-2h 1.3 CSDB内部培训会议一次-2h 2.1 梳理自己45份文件的警戒、警戒、警示、注意命令，并删除同类项，识别相似项并就近标记-2h 2.2 梳理复材组（5人合并后）的警戒、警戒、警示、注意命令，并删除同类项，识别相似项并就近标记-2h 2.3 梳理金属组和复材组的警戒、警戒、警示、注意命令，并删除同类项，识别相似项并就近标记，提交给上飞院，作为资源库录入的输入-2h 3 按录入操作具体情况，更新录入样例两份PPT-2h 4.1 与上飞院、金属组沟通图片库命名事项及具体问题讨论-8h 4.2 组织对Arbortext IsoDraw 7.3版本的转化，降为7.2版本-1h 4.3 6月份复材中心预计陆续发放87份文件，统计87份文件对应信息及对应人员，方便个人进行识别，下载自己相关8份已发布文件，并对图片进行版本识别，确认是7.2版本，7.3版本的继续转化成7.2版本-8h 4.4 按上飞院刘馨阳的要求，更改word文件中的图号，重新生成一版更改后的word文件，作为录入的基础（涉及重命名的文件20份）-16h 4.5 识别复材允许损伤的共用图，并标记-4h 4.6 统计金属复材共用SNS信息，与金属共同确认流水号的起始信息-2h 4.7 按上飞院刘馨阳的要求，一个SNS中进行流水编号的原则，对自己负责的45份文件进行流水编号（初步编号），并填写名称、格式、在文中位置等相关信息，共计338项信息统计-24 5.开展录入工作完成14份文件的录入（图片除外）-14h | N64: =VLOOKUP(E64,订单号!B:C,2,0) -> YZ40000416 | O64: =VLOOKUP(C64,领导干部!B:B,1,0) -> #N/A | Q64: 孟维宇 | R64: 210 | S64: {=VLOOKUP(Q64&R64,IF({1,0},$B$2:$B$330&$F$2:$F$330,$C$2:$C$330),2,)} -> 50722 | T64: {=VLOOKUP(Q64&R64,IF({1,0},$B$2:$B$330&$F$2:$F$330,$D$2:$D$330),2,)} -> 强度室 | U64: {=VLOOKUP(Q64&R64,IF({1,0},$B$2:$B$330&$F$2:$F$330,$E$2:$E$330),2,)} -> C929设计（2025年上飞院） | V64: {=VLOOKUP(Q64&R64,IF({1,0},$B$2:$B$330&$F$2:$F$330,$N$2:$N$330),2,)} -> YZ40000415
A65: =ROW()-1 -> 64 | B65: 魏春生 | C65: =IFERROR(VLOOKUP(B65,[66]工程研发事业部人员名单!B:D,2,0),"") -> 51389 | D65: =IFERROR(VLOOKUP(B65,[66]工程研发事业部人员名单!B:D,3,0),"") -> 系统室 | E65: C919手册优化（2025年复材中心） | F65: =G65+H65+I65+J65 -> 62 | I65: 62 | K65: 系统 | M65: 1.CSDB三方线线上会议，问题梳理及对解答的整理-2h 2.CSDB内部培训会议一次-2h 3.梳理自己27份文件的警戒、警戒、警示、注意命令，并删除同类项，识别相似项并就近标记-1h； 4.开展文件录入工作，完成16份文件的录入（图片除外）-8h； 5.完成12份文件的图片与ISO文件对比一致性-8h； 6.更改12份文件中的图号，重新生成一版更改后的word文件，作为录入的基础-8h； 7.识别复材允许损伤的共用图，并标记-3h； 8.一个SNS中进行流水编号的原则，对自己负责的27份文件进行流水编号（初步编号），并填写名称、格式、在文中位置等相关信息-15h； 9.完成12份技术文件中ISO图片增加热点的工作-15h | N65: =VLOOKUP(E65,订单号!B:C,2,0) -> YZ40000416 | O65: =VLOOKUP(C65,领导干部!B:B,1,0) -> #N/A | Q65: 孟祥瑞 | R65: 200 | S65: {=VLOOKUP(Q65&R65,IF({1,0},$B$2:$B$330&$F$2:$F$330,$C$2:$C$330),2,)} -> 51615 | T65: {=VLOOKUP(Q65&R65,IF({1,0},$B$2:$B$330&$F$2:$F$330,$D$2:$D$330),2,)} -> 结构一室 | U65: {=VLOOKUP(Q65&R65,IF({1,0},$B$2:$B$330&$F$2:$F$330,$E$2:$E$330),2,)} -> C929设计（2025年上飞院） | V65: {=VLOOKUP(Q65&R65,IF({1,0},$B$2:$B$330&$F$2:$F$330,$N$2:$N$330),2,)} -> YZ40000415
A66: =ROW()-1 -> 65 | B66: 赵子维 | C66: =IFERROR(VLOOKUP(B66,[66]工程研发事业部人员名单!B:D,2,0),"") -> 52585 | D66: =IFERROR(VLOOKUP(B66,[66]工程研发事业部人员名单!B:D,3,0),"") -> 系统室 | E66: C919手册优化（2025年复材中心） | F66: =G66+H66+I66+J66 -> 65 | I66: 65 | K66: 系统 | M66: 1.CSDB三方线线上会议，问题梳理及对解答的整理-2h 2.CSDB内部培训会议一次-2h 3.梳理自己48份文件的警戒、警戒、警示、注意命令，并删除同类项，识别相似项并就近标记-2h； 4.开展文件录入工作，完成21份文件的录入（图片除外）-9h； 5.Arbortext IsoDraw 7.3版本的转化，降为7.2版本-1h 6.完成21份文件的图片与ISO文件对比一致性-9h； 7.更改9份文件中的图号，重新生成一版更改后的word文件，作为录入的基础-8h； 8.识别复材允许损伤的共用图，并标记-3h； 9.一个SNS中进行流水编号的原则，对自己负责的48份文件进行流水编号（初步编号），并填写名称、格式、在文中位置等相关信息-17h； 10.完成9份技术文件中ISO图片增加热点的工作-12h | N66: =VLOOKUP(E66,订单号!B:C,2,0) -> YZ40000416 | O66: =VLOOKUP(C66,领导干部!B:B,1,0) -> #N/A | Q66: 牛福春 | R66: 155 | S66: {=VLOOKUP(Q66&R66,IF({1,0},$B$2:$B$330&$F$2:$F$330,$C$2:$C$330),2,)} -> 50710 | T66: {=VLOOKUP(Q66&R66,IF({1,0},$B$2:$B$330&$F$2:$F$330,$D$2:$D$330),2,)} -> 结构二室 | U66: {=VLOOKUP(Q66&R66,IF({1,0},$B$2:$B$330&$F$2:$F$330,$E$2:$E$330),2,)} -> WH1项目结构强度综合 | V66: {=VLOOKUP(Q66&R66,IF({1,0},$B$2:$B$330&$F$2:$F$330,$N$2:$N$330),2,)} -> YZ-RD202428
A67: =ROW()-1 -> 66 | B67: 夏雷 | C67: =IFERROR(VLOOKUP(B67,[66]工程研发事业部人员名单!B:D,2,0),"") -> 52587 | D67: =IFERROR(VLOOKUP(B67,[66]工程研发事业部人员名单!B:D,3,0),"") -> 系统室 | E67: C919手册优化（2025年复材中心） | F67: =G67+H67+I67+J67 -> 62 | I67: 62 | K67: 系统 | M67: 1.CSDB三方线线上会议，问题梳理及对解答的整理-2h 2.CSDB内部培训会议一次-2h 3.梳理自己42份文件的警戒、警戒、警示、注意命令，并删除同类项，识别相似项并就近标记-1h； 4.开展文件录入工作，完成16份文件的录入（图片除外）-8h； 5.完成42份文件的图片与ISO文件对比一致性-8h； 6.更改10份文件中的图号，重新生成一版更改后的word文件，作为录入的基础-8h； 7.识别复材允许损伤的共用图，并标记-3h； 8.一个SNS中进行流水编号的原则，对自己负责的42份文件进行流水编号（初步编号），并填写名称、格式、在文中位置等相关信息-17h； 9.完成12份技术文件中ISO图片增加热点的工作-13h | N67: =VLOOKUP(E67,订单号!B:C,2,0) -> YZ40000416 | O67: =VLOOKUP(C67,领导干部!B:B,1,0) -> #N/A | Q67: 牛建庄 | R67: 194 | S67: {=VLOOKUP(Q67&R67,IF({1,0},$B$2:$B$330&$F$2:$F$330,$C$2:$C$330),2,)} -> 17090 | T67: {=VLOOKUP(Q67&R67,IF({1,0},$B$2:$B$330&$F$2:$F$330,$D$2:$D$330),2,)} -> 联络工程室 | U67: {=VLOOKUP(Q67&R67,IF({1,0},$B$2:$B$330&$F$2:$F$330,$E$2:$E$330),2,)} -> 工程支持 | V67: {=VLOOKUP(Q67&R67,IF({1,0},$B$2:$B$330&$F$2:$F$330,$N$2:$N$330),2,)} -> 10502
...

Sheet X月项目工时 (固定公式)
A1: 序号 | B1: 姓名 | C1: 胸卡号 | D1: 专业室 | E1: 项目简称 | F1: 个人原始项目工时之和/h | G1: 第一年跨专业原始项目工时/h | H1: 第二年跨专业原始项目工时/h | I1: 沈阳工时/h | J1: 市外出差工时/h | K1: 专业 | L1: 工作包 | M1: 主要工作任务 （请简要说明每项设计任务、工时及所属任务通知单编号） 例：序号.工作包-任务通知单编号-设计任务-工时 | N1: 订单号 | O1: 是否国际 | Q1: 姓名 | R1: 最大值项:个人原始项目工时之和/h | S1: 订单号 | T1: 项目简称 | U1: 胸卡号 | V1: 专业室
A2: =ROW()-1 -> 1 | B2: 赵艳秦 | C2: =IFERROR(VLOOKUP(B2,[1]工程研发事业部人员名单!B:D,2,0),"") -> 50022 | D2: =IFERROR(VLOOKUP(B2,[1]工程研发事业部人员名单!B:D,3,0),"") -> 结构二室 | E2: CR929设计（2022年复材中心） | F2: =G2+H2+I2+J2 -> 180 | I2: 180 | K2: 结构 | L2: 前机身 | N2: =VLOOKUP(E2,订单号!B:C,2,0) -> #N/A | O2: =VLOOKUP(C2,领导干部!B:B,1,0) -> #N/A | Q2: 柴宝 | R2: 200 | S2: {=VLOOKUP(Q2&R2,IF({1,0},$B$2:$B$464&$F$2:$F$464,$N$2:$N$464),2,)} -> #N/A | T2: {=VLOOKUP(Q2&R2,IF({1,0},$B$2:$B$464&$F$2:$F$464,$E$2:$E$464),2,)} -> CR929设计（2022年复材中心） | U2: {=VLOOKUP(Q2&R2,IF({1,0},$B$2:$B$464&$F$2:$F$464,$C$2:$C$464),2,)} -> 51944 | V2: {=VLOOKUP(Q2&R2,IF({1,0},$B$2:$B$464&$F$2:$F$464,$D$2:$D$464),2,)} -> 强度室
A3: =ROW()-1 -> 2 | B3: 陈杰 | C3: =IFERROR(VLOOKUP(B3,[1]工程研发事业部人员名单!B:D,2,0),"") -> 25600 | D3: =IFERROR(VLOOKUP(B3,[1]工程研发事业部人员名单!B:D,3,0),"") -> 结构二室 | E3: CR929设计（2022年复材中心） | F3: =G3+H3+I3+J3 -> 160 | I3: 160 | K3: 结构 | L3: 前机身 | N3: =VLOOKUP(E3,订单号!B:C,2,0) -> #N/A | O3: =VLOOKUP(C3,领导干部!B:B,1,0) -> #N/A | Q3: 陈杰 | R3: 160 | S3: {=VLOOKUP(Q3&R3,IF({1,0},$B$2:$B$464&$F$2:$F$464,$N$2:$N$464),2,)} -> #N/A | T3: {=VLOOKUP(Q3&R3,IF({1,0},$B$2:$B$464&$F$2:$F$464,$E$2:$E$464),2,)} -> CR929设计（2022年复材中心） | U3: {=VLOOKUP(Q3&R3,IF({1,0},$B$2:$B$464&$F$2:$F$464,$C$2:$C$464),2,)} -> 25600 | V3: {=VLOOKUP(Q3&R3,IF({1,0},$B$2:$B$464&$F$2:$F$464,$D$2:$D$464),2,)} -> 结构二室
A4: =ROW()-1 -> 3 | B4: 郑石 | C4: =IFERROR(VLOOKUP(B4,[1]工程研发事业部人员名单!B:D,2,0),"") -> 26766 | D4: =IFERROR(VLOOKUP(B4,[1]工程研发事业部人员名单!B:D,3,0),"") -> 强度室 | E4: CR929设计（2022年复材中心） | F4: =G4+H4+I4+J4 -> 300 | I4: 300 | K4: 强度 | L4: 前机身 | N4: =VLOOKUP(E4,订单号!B:C,2,0) -> #N/A | O4: =VLOOKUP(C4,领导干部!B:B,1,0) -> #N/A | Q4: 陈坤 | R4: 227.25 | S4: {=VLOOKUP(Q4&R4,IF({1,0},$B$2:$B$464&$F$2:$F$464,$N$2:$N$464),2,)} -> 10502 | T4: {=VLOOKUP(Q4&R4,IF({1,0},$B$2:$B$464&$F$2:$F$464,$E$2:$E$464),2,)} -> 工程支持 | U4: {=VLOOKUP(Q4&R4,IF({1,0},$B$2:$B$464&$F$2:$F$464,$C$2:$C$464),2,)} -> 51576 | V4: {=VLOOKUP(Q4&R4,IF({1,0},$B$2:$B$464&$F$2:$F$464,$D$2:$D$464),2,)} -> 联络工程室
A5: =ROW()-1 -> 4 | B5: 王琛 | C5: =IFERROR(VLOOKUP(B5,[1]工程研发事业部人员名单!B:D,2,0),"") -> 22291 | D5: =IFERROR(VLOOKUP(B5,[1]工程研发事业部人员名单!B:D,3,0),"") -> 综合技术室 | E5: CR929设计（2022年复材中心） | F5: =G5+H5+I5+J5 -> 30 | H5: 30 | K5: 强度 | L5: 前机身 | N5: =VLOOKUP(E5,订单号!B:C,2,0) -> #N/A | O5: =VLOOKUP(C5,领导干部!B:B,1,0) -> #N/A | Q5: 陈磊 | R5: 252 | S5: {=VLOOKUP(Q5&R5,IF({1,0},$B$2:$B$464&$F$2:$F$464,$N$2:$N$464),2,)} -> #N/A | T5: {=VLOOKUP(Q5&R5,IF({1,0},$B$2:$B$464&$F$2:$F$464,$E$2:$E$464),2,)} -> 1号设计（2022年KTB） | U5: {=VLOOKUP(Q5&R5,IF({1,0},$B$2:$B$464&$F$2:$F$464,$C$2:$C$464),2,)} -> 52180 | V5: {=VLOOKUP(Q5&R5,IF({1,0},$B$2:$B$464&$F$2:$F$464,$D$2:$D$464),2,)} -> 结构一室
A6: =ROW()-1 -> 5 | B6: 张刚 | C6: =IFERROR(VLOOKUP(B6,[1]工程研发事业部人员名单!B:D,2,0),"") -> 50278 | D6: =IFERROR(VLOOKUP(B6,[1]工程研发事业部人员名单!B:D,3,0),"") -> 结构二室 | E6: CR929设计（2022年复材中心） | F6: =G6+H6+I6+J6 -> 208 | J6: 208 | K6: 结构 | L6: 中机身 | N6: =VLOOKUP(E6,订单号!B:C,2,0) -> #N/A | O6: =VLOOKUP(C6,领导干部!B:B,1,0) -> #N/A | Q6: 陈瑞东 | R6: 220 | S6: {=VLOOKUP(Q6&R6,IF({1,0},$B$2:$B$464&$F$2:$F$464,$N$2:$N$464),2,)} -> #N/A | T6: {=VLOOKUP(Q6&R6,IF({1,0},$B$2:$B$464&$F$2:$F$464,$E$2:$E$464),2,)} -> CR929设计（2022年上飞院） | U6: {=VLOOKUP(Q6&R6,IF({1,0},$B$2:$B$464&$F$2:$F$464,$C$2:$C$464),2,)} -> 51181 | V6: {=VLOOKUP(Q6&R6,IF({1,0},$B$2:$B$464&$F$2:$F$464,$D$2:$D$464),2,)} -> 强度室
A7: =ROW()-1 -> 6 | B7: 孟玲俊 | C7: =IFERROR(VLOOKUP(B7,[1]工程研发事业部人员名单!B:D,2,0),"") -> 22298 | D7: =IFERROR(VLOOKUP(B7,[1]工程研发事业部人员名单!B:D,3,0),"") -> 结构二室 | E7: CR929设计（2022年复材中心） | F7: =G7+H7+I7+J7 -> 164 | I7: 164 | K7: 结构 | L7: 中机身 | N7: =VLOOKUP(E7,订单号!B:C,2,0) -> #N/A | O7: =VLOOKUP(C7,领导干部!B:B,1,0) -> #N/A | Q7: 陈志禹 | R7: 145.5 | S7: {=VLOOKUP(Q7&R7,IF({1,0},$B$2:$B$464&$F$2:$F$464,$N$2:$N$464),2,)} -> 10502 | T7: {=VLOOKUP(Q7&R7,IF({1,0},$B$2:$B$464&$F$2:$F$464,$E$2:$E$464),2,)} -> 工程支持 | U7: {=VLOOKUP(Q7&R7,IF({1,0},$B$2:$B$464&$F$2:$F$464,$C$2:$C$464),2,)} -> 17787 | V7: {=VLOOKUP(Q7&R7,IF({1,0},$B$2:$B$464&$F$2:$F$464,$D$2:$D$464),2,)} -> 综合技术室
A8: =ROW()-1 -> 7 | B8: 朱海 | C8: =IFERROR(VLOOKUP(B8,[1]工程研发事业部人员名单!B:D,2,0),"") -> 52232 | D8: =IFERROR(VLOOKUP(B8,[1]工程研发事业部人员名单!B:D,3,0),"") -> 结构二室 | E8: CR929设计（2022年复材中心） | F8: =G8+H8+I8+J8 -> 152 | I8: 152 | K8: 结构 | L8: 中机身 | N8: =VLOOKUP(E8,订单号!B:C,2,0) -> #N/A | O8: =VLOOKUP(C8,领导干部!B:B,1,0) -> #N/A | Q8: 晨曦 | R8: 130 | S8: {=VLOOKUP(Q8&R8,IF({1,0},$B$2:$B$464&$F$2:$F$464,$N$2:$N$464),2,)} -> YZ40000680 | T8: {=VLOOKUP(Q8&R8,IF({1,0},$B$2:$B$464&$F$2:$F$464,$E$2:$E$464),2,)} -> C919设计（2022年上飞院） | U8: {=VLOOKUP(Q8&R8,IF({1,0},$B$2:$B$464&$F$2:$F$464,$C$2:$C$464),2,)} -> 50030 | V8: {=VLOOKUP(Q8&R8,IF({1,0},$B$2:$B$464&$F$2:$F$464,$D$2:$D$464),2,)} -> 总体室
A9: =ROW()-1 -> 8 | B9: 马爽 | C9: =IFERROR(VLOOKUP(B9,[1]工程研发事业部人员名单!B:D,2,0),"") -> 51642 | D9: =IFERROR(VLOOKUP(B9,[1]工程研发事业部人员名单!B:D,3,0),"") -> 结构二室 | E9: CR929设计（2022年复材中心） | F9: =G9+H9+I9+J9 -> 192 | I9: 192 | K9: 结构 | L9: 中机身 | N9: =VLOOKUP(E9,订单号!B:C,2,0) -> #N/A | O9: =VLOOKUP(C9,领导干部!B:B,1,0) -> #N/A | Q9: 褚永鑫 | R9: 293.6 | S9: {=VLOOKUP(Q9&R9,IF({1,0},$B$2:$B$464&$F$2:$F$464,$N$2:$N$464),2,)} -> 10502 | T9: {=VLOOKUP(Q9&R9,IF({1,0},$B$2:$B$464&$F$2:$F$464,$E$2:$E$464),2,)} -> 工程支持 | U9: {=VLOOKUP(Q9&R9,IF({1,0},$B$2:$B$464&$F$2:$F$464,$C$2:$C$464),2,)} -> 22253 | V9: {=VLOOKUP(Q9&R9,IF({1,0},$B$2:$B$464&$F$2:$F$464,$D$2:$D$464),2,)} -> 联络工程室
A10: =ROW()-1 -> 9 | B10: 徐丹 | C10: =IFERROR(VLOOKUP(B10,[1]工程研发事业部人员名单!B:D,2,0),"") -> 51407 | D10: =IFERROR(VLOOKUP(B10,[1]工程研发事业部人员名单!B:D,3,0),"") -> 结构二室 | E10: CR929设计（2022年复材中心） | F10: =G10+H10+I10+J10 -> 166 | I10: 166 | K10: 结构 | L10: 中机身 | N10: =VLOOKUP(E10,订单号!B:C,2,0) -> #N/A | O10: =VLOOKUP(C10,领导干部!B:B,1,0) -> #N/A | Q10: 丛家勇 | R10: 340 | S10: {=VLOOKUP(Q10&R10,IF({1,0},$B$2:$B$464&$F$2:$F$464,$N$2:$N$464),2,)} -> #N/A | T10: {=VLOOKUP(Q10&R10,IF({1,0},$B$2:$B$464&$F$2:$F$464,$E$2:$E$464),2,)} -> CR929设计（2022年上飞院） | U10: {=VLOOKUP(Q10&R10,IF({1,0},$B$2:$B$464&$F$2:$F$464,$C$2:$C$464),2,)} -> 50281 | V10: {=VLOOKUP(Q10&R10,IF({1,0},$B$2:$B$464&$F$2:$F$464,$D$2:$D$464),2,)} -> 结构一室
A11: =ROW()-1 -> 10 | B11: 柴宝 | C11: =IFERROR(VLOOKUP(B11,[1]工程研发事业部人员名单!B:D,2,0),"") -> 51944 | D11: =IFERROR(VLOOKUP(B11,[1]工程研发事业部人员名单!B:D,3,0),"") -> 强度室 | E11: CR929设计（2022年复材中心） | F11: =G11+H11+I11+J11 -> 200 | I11: 200 | K11: 强度 | L11: 中机身 | N11: =VLOOKUP(E11,订单号!B:C,2,0) -> #N/A | O11: =VLOOKUP(C11,领导干部!B:B,1,0) -> #N/A | Q11: 董晓莉 | R11: 220 | S11: {=VLOOKUP(Q11&R11,IF({1,0},$B$2:$B$464&$F$2:$F$464,$N$2:$N$464),2,)} -> #N/A | T11: {=VLOOKUP(Q11&R11,IF({1,0},$B$2:$B$464&$F$2:$F$464,$E$2:$E$464),2,)} -> CR929设计（2022年复材中心） | U11: {=VLOOKUP(Q11&R11,IF({1,0},$B$2:$B$464&$F$2:$F$464,$C$2:$C$464),2,)} -> 51211 | V11: {=VLOOKUP(Q11&R11,IF({1,0},$B$2:$B$464&$F$2:$F$464,$D$2:$D$464),2,)} -> 结构一室
A12: =ROW()-1 -> 11 | B12: 赵永利 | C12: =IFERROR(VLOOKUP(B12,[1]工程研发事业部人员名单!B:D,2,0),"") -> 28161 | D12: =IFERROR(VLOOKUP(B12,[1]工程研发事业部人员名单!B:D,3,0),"") -> 强度室 | E12: CR929设计（2022年复材中心） | F12: =G12+H12+I12+J12 -> 140 | I12: 140 | K12: 强度 | L12: 中机身 | N12: =VLOOKUP(E12,订单号!B:C,2,0) -> #N/A | O12: =VLOOKUP(C12,领导干部!B:B,1,0) -> #N/A | Q12: 杜洪雨 | R12: 220 | S12: {=VLOOKUP(Q12&R12,IF({1,0},$B$2:$B$464&$F$2:$F$464,$N$2:$N$464),2,)} -> YZ40000680 | T12: {=VLOOKUP(Q12&R12,IF({1,0},$B$2:$B$464&$F$2:$F$464,$E$2:$E$464),2,)} -> C919设计（2022年上飞院） | U12: {=VLOOKUP(Q12&R12,IF({1,0},$B$2:$B$464&$F$2:$F$464,$C$2:$C$464),2,)} -> 51170 | V12: {=VLOOKUP(Q12&R12,IF({1,0},$B$2:$B$464&$F$2:$F$464,$D$2:$D$464),2,)} -> 结构二室
A13: =ROW()-1 -> 12 | B13: 付泉铭 | C13: =IFERROR(VLOOKUP(B13,[1]工程研发事业部人员名单!B:D,2,0),"") -> 51555 | D13: =IFERROR(VLOOKUP(B13,[1]工程研发事业部人员名单!B:D,3,0),"") -> 联络工程室 | E13: CR929设计（2022年复材中心） | F13: =G13+H13+I13+J13 -> 65.5 | G13: 65.5 | K13: 强度 | L13: 中机身 | N13: =VLOOKUP(E13,订单号!B:C,2,0) -> #N/A | O13: =VLOOKUP(C13,领导干部!B:B,1,0) -> #N/A | Q13: 付强 | R13: 384.69 | S13: {=VLOOKUP(Q13&R13,IF({1,0},$B$2:$B$464&$F$2:$F$464,$N$2:$N$464),2,)} -> 10502 | T13: {=VLOOKUP(Q13&R13,IF({1,0},$B$2:$B$464&$F$2:$F$464,$E$2:$E$464),2,)} -> 工程支持 | U13: {=VLOOKUP(Q13&R13,IF({1,0},$B$2:$B$464&$F$2:$F$464,$C$2:$C$464),2,)} -> 25549 | V13: {=VLOOKUP(Q13&R13,IF({1,0},$B$2:$B$464&$F$2:$F$464,$D$2:$D$464),2,)} -> 联络工程室
A14: =ROW()-1 -> 13 | B14: 魏春生 | C14: =IFERROR(VLOOKUP(B14,[1]工程研发事业部人员名单!B:D,2,0),"") -> 51389 | D14: =IFERROR(VLOOKUP(B14,[1]工程研发事业部人员名单!B:D,3,0),"") -> 系统室 | E14: CR929设计（2022年复材中心） | F14: =G14+H14+I14+J14 -> 56 | G14: 56 | K14: 强度 | L14: 中机身 | N14: =VLOOKUP(E14,订单号!B:C,2,0) -> #N/A | O14: =VLOOKUP(C14,领导干部!B:B,1,0) -> #N/A | Q14: 付泉铭 | R14: 155 | S14: {=VLOOKUP(Q14&R14,IF({1,0},$B$2:$B$464&$F$2:$F$464,$N$2:$N$464),2,)} -> 0 | T14: {=VLOOKUP(Q14&R14,IF({1,0},$B$2:$B$464&$F$2:$F$464,$E$2:$E$464),2,)} -> 培训工作 | U14: {=VLOOKUP(Q14&R14,IF({1,0},$B$2:$B$464&$F$2:$F$464,$C$2:$C$464),2,)} -> 51555 | V14: {=VLOOKUP(Q14&R14,IF({1,0},$B$2:$B$464&$F$2:$F$464,$D$2:$D$464),2,)} -> 联络工程室
A15: =ROW()-1 -> 14 | B15: 李爱环 | C15: =IFERROR(VLOOKUP(B15,[1]工程研发事业部人员名单!B:D,2,0),"") -> 50726 | D15: =IFERROR(VLOOKUP(B15,[1]工程研发事业部人员名单!B:D,3,0),"") -> 强度室 | E15: CR929设计（2022年复材中心） | F15: =G15+H15+I15+J15 -> 180 | I15: 180 | K15: 强度 | L15: 后压力框 | N15: =VLOOKUP(E15,订单号!B:C,2,0) -> #N/A | O15: =VLOOKUP(C15,领导干部!B:B,1,0) -> #N/A | Q15: 付容容 | R15: 126 | S15: {=VLOOKUP(Q15&R15,IF({1,0},$B$2:$B$464&$F$2:$F$464,$N$2:$N$464),2,)} -> YZ40000680 | T15: {=VLOOKUP(Q15&R15,IF({1,0},$B$2:$B$464&$F$2:$F$464,$E$2:$E$464),2,)} -> C919设计（2022年上飞院） | U15: {=VLOOKUP(Q15&R15,IF({1,0},$B$2:$B$464&$F$2:$F$464,$C$2:$C$464),2,)} -> 51183 | V15: {=VLOOKUP(Q15&R15,IF({1,0},$B$2:$B$464&$F$2:$F$464,$D$2:$D$464),2,)} -> 结构一室
A16: =ROW()-1 -> 15 | B16: 牛福春 | C16: =IFERROR(VLOOKUP(B16,[1]工程研发事业部人员名单!B:D,2,0),"") -> 50710 | D16: =IFERROR(VLOOKUP(B16,[1]工程研发事业部人员名单!B:D,3,0),"") -> 结构二室 | E16: CR929设计（2022年复材中心） | F16: =G16+H16+I16+J16 -> 168 | I16: 168 | K16: 结构 | L16: 后机身 | N16: =VLOOKUP(E16,订单号!B:C,2,0) -> #N/A | O16: =VLOOKUP(C16,领导干部!B:B,1,0) -> #N/A | Q16: 高秉芳 | R16: 378.85 | S16: {=VLOOKUP(Q16&R16,IF({1,0},$B$2:$B$464&$F$2:$F$464,$N$2:$N$464),2,)} -> 10502 | T16: {=VLOOKUP(Q16&R16,IF({1,0},$B$2:$B$464&$F$2:$F$464,$E$2:$E$464),2,)} -> 工程支持 | U16: {=VLOOKUP(Q16&R16,IF({1,0},$B$2:$B$464&$F$2:$F$464,$C$2:$C$464),2,)} -> 26688 | V16: {=VLOOKUP(Q16&R16,IF({1,0},$B$2:$B$464&$F$2:$F$464,$D$2:$D$464),2,)} -> 联络工程室
A17: =ROW()-1 -> 16 | B17: 康霞 | C17: =IFERROR(VLOOKUP(B17,[1]工程研发事业部人员名单!B:D,2,0),"") -> 52132 | D17: =IFERROR(VLOOKUP(B17,[1]工程研发事业部人员名单!B:D,3,0),"") -> 结构二室 | E17: CR929设计（2022年复材中心） | F17: =G17+H17+I17+J17 -> 30 | I17: 30 | K17: 结构 | L17: 后机身 | N17: =VLOOKUP(E17,订单号!B:C,2,0) -> #N/A | O17: =VLOOKUP(C17,领导干部!B:B,1,0) -> #N/A | Q17: 高奇 | R17: 226.46 | S17: {=VLOOKUP(Q17&R17,IF({1,0},$B$2:$B$464&$F$2:$F$464,$N$2:$N$464),2,)} -> 10502 | T17: {=VLOOKUP(Q17&R17,IF({1,0},$B$2:$B$464&$F$2:$F$464,$E$2:$E$464),2,)} -> 工程支持 | U17: {=VLOOKUP(Q17&R17,IF({1,0},$B$2:$B$464&$F$2:$F$464,$C$2:$C$464),2,)} -> 17732 | V17: {=VLOOKUP(Q17&R17,IF({1,0},$B$2:$B$464&$F$2:$F$464,$D$2:$D$464),2,)} -> 联络工程室
A18: =ROW()-1 -> 17 | B18: 周莫普 | C18: =IFERROR(VLOOKUP(B18,[1]工程研发事业部人员名单!B:D,2,0),"") -> 51397 | D18: =IFERROR(VLOOKUP(B18,[1]工程研发事业部人员名单!B:D,3,0),"") -> 结构二室 | E18: CR929设计（2022年复材中心） | F18: =G18+H18+I18+J18 -> 168 | I18: 168 | K18: 结构 | L18: 后机身 | N18: =VLOOKUP(E18,订单号!B:C,2,0) -> #N/A | O18: =VLOOKUP(C18,领导干部!B:B,1,0) -> #N/A | Q18: 葛春生 | R18: 170 | S18: {=VLOOKUP(Q18&R18,IF({1,0},$B$2:$B$464&$F$2:$F$464,$N$2:$N$464),2,)} -> #N/A | T18: {=VLOOKUP(Q18&R18,IF({1,0},$B$2:$B$464&$F$2:$F$464,$E$2:$E$464),2,)} -> CR929设计（2022年复材中心） | U18: {=VLOOKUP(Q18&R18,IF({1,0},$B$2:$B$464&$F$2:$F$464,$C$2:$C$464),2,)} -> 51410 | V18: {=VLOOKUP(Q18&R18,IF({1,0},$B$2:$B$464&$F$2:$F$464,$D$2:$D$464),2,)} -> 结构一室
A19: =ROW()-1 -> 18 | B19: 贾永亮 | C19: =IFERROR(VLOOKUP(B19,[1]工程研发事业部人员名单!B:D,2,0),"") -> 52131 | D19: =IFERROR(VLOOKUP(B19,[1]工程研发事业部人员名单!B:D,3,0),"") -> 结构二室 | E19: CR929设计（2022年复材中心） | F19: =G19+H19+I19+J19 -> 168 | I19: 168 | K19: 结构 | L19: 后机身 | N19: =VLOOKUP(E19,订单号!B:C,2,0) -> #N/A | O19: =VLOOKUP(C19,领导干部!B:B,1,0) -> #N/A | Q19: 耿璐璐 | R19: 138.17 | S19: {=VLOOKUP(Q19&R19,IF({1,0},$B$2:$B$464&$F$2:$F$464,$N$2:$N$464),2,)} -> 10502 | T19: {=VLOOKUP(Q19&R19,IF({1,0},$B$2:$B$464&$F$2:$F$464,$E$2:$E$464),2,)} -> 工程支持 | U19: {=VLOOKUP(Q19&R19,IF({1,0},$B$2:$B$464&$F$2:$F$464,$C$2:$C$464),2,)} -> 51405 | V19: {=VLOOKUP(Q19&R19,IF({1,0},$B$2:$B$464&$F$2:$F$464,$D$2:$D$464),2,)} -> 综合技术室
A20: =ROW()-1 -> 19 | B20: 许美娟 | C20: =IFERROR(VLOOKUP(B20,[1]工程研发事业部人员名单!B:D,2,0),"") -> 51194 | D20: =IFERROR(VLOOKUP(B20,[1]工程研发事业部人员名单!B:D,3,0),"") -> 强度室 | E20: CR929设计（2022年复材中心） | F20: =G20+H20+I20+J20 -> 110 | I20: 110 | K20: 强度 | L20: 后机身 | N20: =VLOOKUP(E20,订单号!B:C,2,0) -> #N/A | O20: =VLOOKUP(C20,领导干部!B:B,1,0) -> #N/A | Q20: 郭静 | R20: 336.65 | S20: {=VLOOKUP(Q20&R20,IF({1,0},$B$2:$B$464&$F$2:$F$464,$N$2:$N$464),2,)} -> 10502 | T20: {=VLOOKUP(Q20&R20,IF({1,0},$B$2:$B$464&$F$2:$F$464,$E$2:$E$464),2,)} -> 工程支持 | U20: {=VLOOKUP(Q20&R20,IF({1,0},$B$2:$B$464&$F$2:$F$464,$C$2:$C$464),2,)} -> 50027 | V20: {=VLOOKUP(Q20&R20,IF({1,0},$B$2:$B$464&$F$2:$F$464,$D$2:$D$464),2,)} -> 联络工程室
A21: =ROW()-1 -> 20 | B21: 刘可佳 | C21: =IFERROR(VLOOKUP(B21,[1]工程研发事业部人员名单!B:D,2,0),"") -> 51793 | D21: =IFERROR(VLOOKUP(B21,[1]工程研发事业部人员名单!B:D,3,0),"") -> 强度室 | E21: CR929设计（2022年复材中心） | F21: =G21+H21+I21+J21 -> 50 | I21: 50 | K21: 强度 | L21: 后机身 | N21: =VLOOKUP(E21,订单号!B:C,2,0) -> #N/A | O21: =VLOOKUP(C21,领导干部!B:B,1,0) -> #N/A | Q21: 郭晓庆 | R21: 283.5 | S21: {=VLOOKUP(Q21&R21,IF({1,0},$B$2:$B$464&$F$2:$F$464,$N$2:$N$464),2,)} -> YZ40000680 | T21: {=VLOOKUP(Q21&R21,IF({1,0},$B$2:$B$464&$F$2:$F$464,$E$2:$E$464),2,)} -> C919设计（2022年上飞院） | U21: {=VLOOKUP(Q21&R21,IF({1,0},$B$2:$B$464&$F$2:$F$464,$C$2:$C$464),2,)} -> 50275 | V21: {=VLOOKUP(Q21&R21,IF({1,0},$B$2:$B$464&$F$2:$F$464,$D$2:$D$464),2,)} -> 结构一室
A22: =ROW()-1 -> 21 | B22: 王岩 | C22: =IFERROR(VLOOKUP(B22,[1]工程研发事业部人员名单!B:D,2,0),"") -> 51175 | D22: =IFERROR(VLOOKUP(B22,[1]工程研发事业部人员名单!B:D,3,0),"") -> 强度室 | E22: CR929设计（2022年复材中心） | F22: =G22+H22+I22+J22 -> 122.5 | I22: 122.5 | K22: 强度 | L22: 后机身 | N22: =VLOOKUP(E22,订单号!B:C,2,0) -> #N/A | O22: =VLOOKUP(C22,领导干部!B:B,1,0) -> #N/A | Q22: 韩南逍 | R22: 157.5 | S22: {=VLOOKUP(Q22&R22,IF({1,0},$B$2:$B$464&$F$2:$F$464,$N$2:$N$464),2,)} -> 10502 | T22: {=VLOOKUP(Q22&R22,IF({1,0},$B$2:$B$464&$F$2:$F$464,$E$2:$E$464),2,)} -> 工程支持 | U22: {=VLOOKUP(Q22&R22,IF({1,0},$B$2:$B$464&$F$2:$F$464,$C$2:$C$464),2,)} -> 50029 | V22: {=VLOOKUP(Q22&R22,IF({1,0},$B$2:$B$464&$F$2:$F$464,$D$2:$D$464),2,)} -> 综合技术室
A23: =ROW()-1 -> 22 | B23: 马雪菲 | C23: =IFERROR(VLOOKUP(B23,[1]工程研发事业部人员名单!B:D,2,0),"") -> 52560 | D23: =IFERROR(VLOOKUP(B23,[1]工程研发事业部人员名单!B:D,3,0),"") -> 强度室 | E23: CR929设计（2022年复材中心） | F23: =G23+H23+I23+J23 -> 80 | I23: 80 | K23: 强度 | L23: 后机身 | N23: =VLOOKUP(E23,订单号!B:C,2,0) -> #N/A | O23: =VLOOKUP(C23,领导干部!B:B,1,0) -> #N/A | Q23: 何续斌 | R23: 255 | S23: {=VLOOKUP(Q23&R23,IF({1,0},$B$2:$B$464&$F$2:$F$464,$N$2:$N$464),2,)} -> YZ40000680 | T23: {=VLOOKUP(Q23&R23,IF({1,0},$B$2:$B$464&$F$2:$F$464,$E$2:$E$464),2,)} -> C919设计（2022年上飞院） | U23: {=VLOOKUP(Q23&R23,IF({1,0},$B$2:$B$464&$F$2:$F$464,$C$2:$C$464),2,)} -> 50871 | V23: {=VLOOKUP(Q23&R23,IF({1,0},$B$2:$B$464&$F$2:$F$464,$D$2:$D$464),2,)} -> 强度室
A24: =ROW()-1 -> 23 | B24: 刘成 | C24: =IFERROR(VLOOKUP(B24,[1]工程研发事业部人员名单!B:D,2,0),"") -> 51860 | D24: =IFERROR(VLOOKUP(B24,[1]工程研发事业部人员名单!B:D,3,0),"") -> 总体室 | E24: CR929设计（2022年复材中心） | F24: =G24+H24+I24+J24 -> 65 | H24: 65 | K24: 强度 | L24: 后机身 | N24: =VLOOKUP(E24,订单号!B:C,2,0) -> #N/A | O24: =VLOOKUP(C24,领导干部!B:B,1,0) -> #N/A | Q24: 黄文超 | R24: 120 | S24: {=VLOOKUP(Q24&R24,IF({1,0},$B$2:$B$464&$F$2:$F$464,$N$2:$N$464),2,)} -> #N/A | T24: {=VLOOKUP(Q24&R24,IF({1,0},$B$2:$B$464&$F$2:$F$464,$E$2:$E$464),2,)} -> CR929设计（2022年复材中心） | U24: {=VLOOKUP(Q24&R24,IF({1,0},$B$2:$B$464&$F$2:$F$464,$C$2:$C$464),2,)} -> 51200 | V24: {=VLOOKUP(Q24&R24,IF({1,0},$B$2:$B$464&$F$2:$F$464,$D$2:$D$464),2,)} -> 强度室
A25: =ROW()-1 -> 24 | B25: 康霞 | C25: =IFERROR(VLOOKUP(B25,[1]工程研发事业部人员名单!B:D,2,0),"") -> 52132 | D25: =IFERROR(VLOOKUP(B25,[1]工程研发事业部人员名单!B:D,3,0),"") -> 结构二室 | E25: CR929设计（2022年复材中心） | F25: =G25+H25+I25+J25 -> 78 | H25: 78 | K25: 强度 | L25: 后机身 | N25: =VLOOKUP(E25,订单号!B:C,2,0) -> #N/A | O25: =VLOOKUP(C25,领导干部!B:B,1,0) -> #N/A | Q25: 霍东旭 | R25: 393.65 | S25: {=VLOOKUP(Q25&R25,IF({1,0},$B$2:$B$464&$F$2:$F$464,$N$2:$N$464),2,)} -> 10502 | T25: {=VLOOKUP(Q25&R25,IF({1,0},$B$2:$B$464&$F$2:$F$464,$E$2:$E$464),2,)} -> 工程支持 | U25: {=VLOOKUP(Q25&R25,IF({1,0},$B$2:$B$464&$F$2:$F$464,$C$2:$C$464),2,)} -> 51941 | V25: {=VLOOKUP(Q25&R25,IF({1,0},$B$2:$B$464&$F$2:$F$464,$D$2:$D$464),2,)} -> 联络工程室
A26: =ROW()-1 -> 25 | B26: 王琛 | C26: =IFERROR(VLOOKUP(B26,[1]工程研发事业部人员名单!B:D,2,0),"") -> 22291 | D26: =IFERROR(VLOOKUP(B26,[1]工程研发事业部人员名单!B:D,3,0),"") -> 综合技术室 | E26: CR929设计（2022年复材中心） | F26: =G26+H26+I26+J26 -> 26 | H26: 26 | K26: 强度 | L26: 后机身 | N26: =VLOOKUP(E26,订单号!B:C,2,0) -> #N/A | O26: =VLOOKUP(C26,领导干部!B:B,1,0) -> #N/A | Q26: 纪可 | R26: 130 | S26: {=VLOOKUP(Q26&R26,IF({1,0},$B$2:$B$464&$F$2:$F$464,$N$2:$N$464),2,)} -> YZ40000680 | T26: {=VLOOKUP(Q26&R26,IF({1,0},$B$2:$B$464&$F$2:$F$464,$E$2:$E$464),2,)} -> C919设计（2022年上飞院） | U26: {=VLOOKUP(Q26&R26,IF({1,0},$B$2:$B$464&$F$2:$F$464,$C$2:$C$464),2,)} -> 26689 | V26: {=VLOOKUP(Q26&R26,IF({1,0},$B$2:$B$464&$F$2:$F$464,$D$2:$D$464),2,)} -> 强度室
A27: =ROW()-1 -> 26 | B27: 孔婷婷 | C27: =IFERROR(VLOOKUP(B27,[1]工程研发事业部人员名单!B:D,2,0),"") -> 23525 | D27: =IFERROR(VLOOKUP(B27,[1]工程研发事业部人员名单!B:D,3,0),"") -> 强度室 | E27: CR929设计（2022年复材中心） | F27: =G27+H27+I27+J27 -> 140 | I27: 140 | K27: 强度 | L27: 机翼 | N27: =VLOOKUP(E27,订单号!B:C,2,0) -> #N/A | O27: =VLOOKUP(C27,领导干部!B:B,1,0) -> #N/A | Q27: 贾永亮 | R27: 168 | S27: {=VLOOKUP(Q27&R27,IF({1,0},$B$2:$B$464&$F$2:$F$464,$N$2:$N$464),2,)} -> #N/A | T27: {=VLOOKUP(Q27&R27,IF({1,0},$B$2:$B$464&$F$2:$F$464,$E$2:$E$464),2,)} -> CR929设计（2022年复材中心） | U27: {=VLOOKUP(Q27&R27,IF({1,0},$B$2:$B$464&$F$2:$F$464,$C$2:$C$464),2,)} -> 52131 | V27: {=VLOOKUP(Q27&R27,IF({1,0},$B$2:$B$464&$F$2:$F$464,$D$2:$D$464),2,)} -> 结构二室
A28: =ROW()-1 -> 27 | B28: 黄文超 | C28: =IFERROR(VLOOKUP(B28,[1]工程研发事业部人员名单!B:D,2,0),"") -> 51200 | D28: =IFERROR(VLOOKUP(B28,[1]工程研发事业部人员名单!B:D,3,0),"") -> 强度室 | E28: CR929设计（2022年复材中心） | F28: =G28+H28+I28+J28 -> 120 | I28: 120 | K28: 强度 | L28: 机翼 | N28: =VLOOKUP(E28,订单号!B:C,2,0) -> #N/A | O28: =VLOOKUP(C28,领导干部!B:B,1,0) -> #N/A | Q28: 焦凯 | R28: 150 | S28: {=VLOOKUP(Q28&R28,IF({1,0},$B$2:$B$464&$F$2:$F$464,$N$2:$N$464),2,)} -> YZ40000680 | T28: {=VLOOKUP(Q28&R28,IF({1,0},$B$2:$B$464&$F$2:$F$464,$E$2:$E$464),2,)} -> C919设计（2022年上飞院） | U28: {=VLOOKUP(Q28&R28,IF({1,0},$B$2:$B$464&$F$2:$F$464,$C$2:$C$464),2,)} -> 52342 | V28: {=VLOOKUP(Q28&R28,IF({1,0},$B$2:$B$464&$F$2:$F$464,$D$2:$D$464),2,)} -> 强度室
A29: =ROW()-1 -> 28 | B29: 朱照泽 | C29: =IFERROR(VLOOKUP(B29,[1]工程研发事业部人员名单!B:D,2,0),"") -> 51763 | D29: =IFERROR(VLOOKUP(B29,[1]工程研发事业部人员名单!B:D,3,0),"") -> 强度室 | E29: CR929设计（2022年复材中心） | F29: =G29+H29+I29+J29 -> 120 | I29: 120 | K29: 强度 | L29: 机翼 | N29: =VLOOKUP(E29,订单号!B:C,2,0) -> #N/A | O29: =VLOOKUP(C29,领导干部!B:B,1,0) -> #N/A | Q29: 靳海丰 | R29: 200 | S29: {=VLOOKUP(Q29&R29,IF({1,0},$B$2:$B$464&$F$2:$F$464,$N$2:$N$464),2,)} -> #N/A | T29: {=VLOOKUP(Q29&R29,IF({1,0},$B$2:$B$464&$F$2:$F$464,$E$2:$E$464),2,)} -> C919设计（2021年上飞院） | U29: {=VLOOKUP(Q29&R29,IF({1,0},$B$2:$B$464&$F$2:$F$464,$C$2:$C$464),2,)} -> 51158 | V29: {=VLOOKUP(Q29&R29,IF({1,0},$B$2:$B$464&$F$2:$F$464,$D$2:$D$464),2,)} -> 强度室
A30: =ROW()-1 -> 29 | B30: 闫洪乐 | C30: =IFERROR(VLOOKUP(B30,[1]工程研发事业部人员名单!B:D,2,0),"") -> 52347 | D30: =IFERROR(VLOOKUP(B30,[1]工程研发事业部人员名单!B:D,3,0),"") -> 强度室 | E30: CR929设计（2022年复材中心） | F30: =G30+H30+I30+J30 -> 120 | I30: 120 | K30: 强度 | L30: 机翼 | N30: =VLOOKUP(E30,订单号!B:C,2,0) -> #N/A | O30: =VLOOKUP(C30,领导干部!B:B,1,0) -> #N/A | Q30: 康霞 | R30: 90 | S30: {=VLOOKUP(Q30&R30,IF({1,0},$B$2:$B$464&$F$2:$F$464,$N$2:$N$464),2,)} -> YZ40000680 | T30: {=VLOOKUP(Q30&R30,IF({1,0},$B$2:$B$464&$F$2:$F$464,$E$2:$E$464),2,)} -> C919设计（2022年上飞院） | U30: {=VLOOKUP(Q30&R30,IF({1,0},$B$2:$B$464&$F$2:$F$464,$C$2:$C$464),2,)} -> 52132 | V30: {=VLOOKUP(Q30&R30,IF({1,0},$B$2:$B$464&$F$2:$F$464,$D$2:$D$464),2,)} -> 结构二室
A31: =ROW()-1 -> 30 | B31: 王呈呈 | C31: =IFERROR(VLOOKUP(B31,[1]工程研发事业部人员名单!B:D,2,0),"") -> 51196 | D31: =IFERROR(VLOOKUP(B31,[1]工程研发事业部人员名单!B:D,3,0),"") -> 强度室 | E31: CR929设计（2022年复材中心） | F31: =G31+H31+I31+J31 -> 120 | I31: 120 | K31: 强度 | L31: 机翼 | N31: =VLOOKUP(E31,订单号!B:C,2,0) -> #N/A | O31: =VLOOKUP(C31,领导干部!B:B,1,0) -> #N/A | Q31: 康志明 | R31: 240 | S31: {=VLOOKUP(Q31&R31,IF({1,0},$B$2:$B$464&$F$2:$F$464,$N$2:$N$464),2,)} -> #N/A | T31: {=VLOOKUP(Q31&R31,IF({1,0},$B$2:$B$464&$F$2:$F$464,$E$2:$E$464),2,)} -> 1号设计（2022年KTB） | U31: {=VLOOKUP(Q31&R31,IF({1,0},$B$2:$B$464&$F$2:$F$464,$C$2:$C$464),2,)} -> 25765 | V31: {=VLOOKUP(Q31&R31,IF({1,0},$B$2:$B$464&$F$2:$F$464,$D$2:$D$464),2,)} -> 结构一室
A32: =ROW()-1 -> 31 | B32: 李妍 | C32: =IFERROR(VLOOKUP(B32,[1]工程研发事业部人员名单!B:D,2,0),"") -> 51435 | D32: =IFERROR(VLOOKUP(B32,[1]工程研发事业部人员名单!B:D,3,0),"") -> 系统室 | E32: CR929设计（2022年复材中心） | F32: =G32+H32+I32+J32 -> 120 | G32: 120 | K32: 强度 | L32: 机翼 | N32: =VLOOKUP(E32,订单号!B:C,2,0) -> #N/A | O32: =VLOOKUP(C32,领导干部!B:B,1,0) -> #N/A | Q32: 孔婷婷 | R32: 140 | S32: {=VLOOKUP(Q32&R32,IF({1,0},$B$2:$B$464&$F$2:$F$464,$N$2:$N$464),2,)} -> #N/A | T32: {=VLOOKUP(Q32&R32,IF({1,0},$B$2:$B$464&$F$2:$F$464,$E$2:$E$464),2,)} -> CR929设计（2022年复材中心） | U32: {=VLOOKUP(Q32&R32,IF({1,0},$B$2:$B$464&$F$2:$F$464,$C$2:$C$464),2,)} -> 23525 | V32: {=VLOOKUP(Q32&R32,IF({1,0},$B$2:$B$464&$F$2:$F$464,$D$2:$D$464),2,)} -> 强度室
A33: =ROW()-1 -> 32 | B33: 宋凯 | C33: =IFERROR(VLOOKUP(B33,[1]工程研发事业部人员名单!B:D,2,0),"") -> 51951 | D33: =IFERROR(VLOOKUP(B33,[1]工程研发事业部人员名单!B:D,3,0),"") -> 系统室 | E33: CR929设计（2022年复材中心） | F33: =G33+H33+I33+J33 -> 60 | G33: 60 | K33: 强度 | L33: 机翼 | N33: =VLOOKUP(E33,订单号!B:C,2,0) -> #N/A | O33: =VLOOKUP(C33,领导干部!B:B,1,0) -> #N/A | Q33: 李爱环 | R33: 180 | S33: {=VLOOKUP(Q33&R33,IF({1,0},$B$2:$B$464&$F$2:$F$464,$N$2:$N$464),2,)} -> #N/A | T33: {=VLOOKUP(Q33&R33,IF({1,0},$B$2:$B$464&$F$2:$F$464,$E$2:$E$464),2,)} -> CR929设计（2022年复材中心） | U33: {=VLOOKUP(Q33&R33,IF({1,0},$B$2:$B$464&$F$2:$F$464,$C$2:$C$464),2,)} -> 50726 | V33: {=VLOOKUP(Q33&R33,IF({1,0},$B$2:$B$464&$F$2:$F$464,$D$2:$D$464),2,)} -> 强度室
A34: =ROW()-1 -> 33 | B34: 万方 | C34: =IFERROR(VLOOKUP(B34,[1]工程研发事业部人员名单!B:D,2,0),"") -> 51387 | D34: =IFERROR(VLOOKUP(B34,[1]工程研发事业部人员名单!B:D,3,0),"") -> 系统室 | E34: CR929设计（2022年复材中心） | F34: =G34+H34+I34+J34 -> 100 | G34: 100 | K34: 强度 | L34: 机翼 | N34: =VLOOKUP(E34,订单号!B:C,2,0) -> #N/A | O34: =VLOOKUP(C34,领导干部!B:B,1,0) -> #N/A | Q34: 李金鹰 | R34: 75 | S34: {=VLOOKUP(Q34&R34,IF({1,0},$B$2:$B$464&$F$2:$F$464,$N$2:$N$464),2,)} -> 0 | T34: {=VLOOKUP(Q34&R34,IF({1,0},$B$2:$B$464&$F$2:$F$464,$E$2:$E$464),2,)} -> 培训工作 | U34: {=VLOOKUP(Q34&R34,IF({1,0},$B$2:$B$464&$F$2:$F$464,$C$2:$C$464),2,)} -> 51227 | V34: {=VLOOKUP(Q34&R34,IF({1,0},$B$2:$B$464&$F$2:$F$464,$D$2:$D$464),2,)} -> 结构一室
A35: =ROW()-1 -> 34 | B35: 骆美玲 | C35: =IFERROR(VLOOKUP(B35,[1]工程研发事业部人员名单!B:D,2,0),"") -> 50713 | D35: =IFERROR(VLOOKUP(B35,[1]工程研发事业部人员名单!B:D,3,0),"") -> 系统室 | E35: CR929设计（2022年复材中心） | F35: =G35+H35+I35+J35 -> 5 | G35: 5 | K35: 强度 | L35: 机翼 | N35: =VLOOKUP(E35,订单号!B:C,2,0) -> #N/A | O35: =VLOOKUP(C35,领导干部!B:B,1,0) -> #N/A | Q35: 李其鹏 | R35: 150.5 | S35: {=VLOOKUP(Q35&R35,IF({1,0},$B$2:$B$464&$F$2:$F$464,$N$2:$N$464),2,)} -> 10502 | T35: {=VLOOKUP(Q35&R35,IF({1,0},$B$2:$B$464&$F$2:$F$464,$E$2:$E$464),2,)} -> 工程支持 | U35: {=VLOOKUP(Q35&R35,IF({1,0},$B$2:$B$464&$F$2:$F$464,$C$2:$C$464),2,)} -> 51429 | V35: {=VLOOKUP(Q35&R35,IF({1,0},$B$2:$B$464&$F$2:$F$464,$D$2:$D$464),2,)} -> 综合技术室
A36: =ROW()-1 -> 35 | B36: 魏春生 | C36: =IFERROR(VLOOKUP(B36,[1]工程研发事业部人员名单!B:D,2,0),"") -> 51389 | D36: =IFERROR(VLOOKUP(B36,[1]工程研发事业部人员名单!B:D,3,0),"") -> 系统室 | E36: CR929设计（2022年复材中心） | F36: =G36+H36+I36+J36 -> 5 | G36: 5 | K36: 强度 | L36: 机翼 | N36: =VLOOKUP(E36,订单号!B:C,2,0) -> #N/A | O36: =VLOOKUP(C36,领导干部!B:B,1,0) -> #N/A | Q36: 李森 | R36: 260 | S36: {=VLOOKUP(Q36&R36,IF({1,0},$B$2:$B$464&$F$2:$F$464,$N$2:$N$464),2,)} -> #N/A | T36: {=VLOOKUP(Q36&R36,IF({1,0},$B$2:$B$464&$F$2:$F$464,$E$2:$E$464),2,)} -> 1号设计（2022年KTB） | U36: {=VLOOKUP(Q36&R36,IF({1,0},$B$2:$B$464&$F$2:$F$464,$C$2:$C$464),2,)} -> 17238 | V36: {=VLOOKUP(Q36&R36,IF({1,0},$B$2:$B$464&$F$2:$F$464,$D$2:$D$464),2,)} -> 结构二室
A37: =ROW()-1 -> 36 | B37: 刘凯男 | C37: =IFERROR(VLOOKUP(B37,[1]工程研发事业部人员名单!B:D,2,0),"") -> 52156 | D37: =IFERROR(VLOOKUP(B37,[1]工程研发事业部人员名单!B:D,3,0),"") -> 系统室 | E37: CR929设计（2022年复材中心） | F37: =G37+H37+I37+J37 -> 150 | G37: 150 | K37: 强度 | L37: 机翼 | N37: =VLOOKUP(E37,订单号!B:C,2,0) -> #N/A | O37: =VLOOKUP(C37,领导干部!B:B,1,0) -> #N/A | Q37: 李守玺 | R37: 300 | S37: {=VLOOKUP(Q37&R37,IF({1,0},$B$2:$B$464&$F$2:$F$464,$N$2:$N$464),2,)} -> #N/A | T37: {=VLOOKUP(Q37&R37,IF({1,0},$B$2:$B$464&$F$2:$F$464,$E$2:$E$464),2,)} -> 1号设计（2022年KTB） | U37: {=VLOOKUP(Q37&R37,IF({1,0},$B$2:$B$464&$F$2:$F$464,$C$2:$C$464),2,)} -> 25763 | V37: {=VLOOKUP(Q37&R37,IF({1,0},$B$2:$B$464&$F$2:$F$464,$D$2:$D$464),2,)} -> 结构一室
A38: =ROW()-1 -> 37 | B38: 杨春 | C38: =IFERROR(VLOOKUP(B38,[1]工程研发事业部人员名单!B:D,2,0),"") -> 51624 | D38: =IFERROR(VLOOKUP(B38,[1]工程研发事业部人员名单!B:D,3,0),"") -> 结构一室 | E38: CR929设计（2022年复材中心） | F38: =G38+H38+I38+J38 -> 80 | I38: 80 | K38: 结构 | L38: 平尾 | N38: =VLOOKUP(E38,订单号!B:C,2,0) -> #N/A | O38: =VLOOKUP(C38,领导干部!B:B,1,0) -> #N/A | Q38: 李湘芝 | R38: 287.92 | S38: {=VLOOKUP(Q38&R38,IF({1,0},$B$2:$B$464&$F$2:$F$464,$N$2:$N$464),2,)} -> 10502 | T38: {=VLOOKUP(Q38&R38,IF({1,0},$B$2:$B$464&$F$2:$F$464,$E$2:$E$464),2,)} -> 工程支持 | U38: {=VLOOKUP(Q38&R38,IF({1,0},$B$2:$B$464&$F$2:$F$464,$C$2:$C$464),2,)} -> 50019 | V38: {=VLOOKUP(Q38&R38,IF({1,0},$B$2:$B$464&$F$2:$F$464,$D$2:$D$464),2,)} -> 联络工程室
